2017-04-01 23:47:00 - INFO - views:login:350 - User anshul successfully authenticated
2017-04-01 23:49:05 - INFO - views:login:350 - User anshul successfully authenticated
2017-04-01 23:51:24 - INFO - views:login:350 - User anshul successfully authenticated
2017-04-02 00:09:56 - INFO - views:login:350 - User anshul successfully authenticated
2017-04-02 03:24:47 - INFO - views:login:350 - User anshul successfully authenticated
2017-04-02 17:02:48 - INFO - views:login:350 - User anshul successfully authenticated
2017-04-02 17:03:09 - INFO - views:logout:372 - User anshul successfully logged out
2017-04-02 17:03:25 - INFO - views:login:350 - User divyesh successfully authenticated
2017-04-03 00:09:31 - INFO - views:logout:372 - User divyesh successfully logged out
2017-04-03 00:09:39 - INFO - views:login:350 - User ranjana successfully authenticated
2017-04-03 01:05:00 - INFO - views:logout:372 - User ranjana successfully logged out
2017-04-03 01:05:05 - INFO - views:login:350 - User anshul successfully authenticated
2017-04-03 01:06:06 - INFO - views:logout:372 - User anshul successfully logged out
2017-04-03 01:06:11 - INFO - views:login:350 - User ranjana successfully authenticated
2017-04-03 18:00:46 - INFO - views:login:350 - User anshul successfully authenticated
2017-04-03 18:01:49 - INFO - views:logout:372 - User anshul successfully logged out
2017-04-03 18:01:56 - INFO - views:login:350 - User ranjana successfully authenticated
2017-04-03 18:02:11 - INFO - guide_views:guide_evaluate_unevaluated_abstract:86 - SHANU
2017-04-03 18:02:14 - INFO - views:logout:372 - User ranjana successfully logged out
2017-04-03 18:02:23 - INFO - views:login:350 - User anshul successfully authenticated
2017-04-03 18:10:38 - ERROR - base:handle_uncaught_exception:284 - Internal Server Error: /user/notifications/
Traceback (most recent call last):
  File "E:\Education\GitHub Projects\PhDPortal\env\lib\site-packages\django\template\base.py", line 879, in _resolve_lookup
    current = current[bit]
  File "E:\Education\GitHub Projects\PhDPortal\env\lib\site-packages\django\template\context.py", line 77, in __getitem__
    raise KeyError(key)
KeyError: 'TIME_ZONE'

During handling of the above exception, another exception occurred:

Traceback (most recent call last):
  File "E:\Education\GitHub Projects\PhDPortal\env\lib\site-packages\django\template\base.py", line 885, in _resolve_lookup
    if isinstance(current, BaseContext) and getattr(type(current), bit):
AttributeError: type object 'RequestContext' has no attribute 'TIME_ZONE'

During handling of the above exception, another exception occurred:

Traceback (most recent call last):
  File "E:\Education\GitHub Projects\PhDPortal\env\lib\site-packages\django\template\base.py", line 894, in _resolve_lookup
    current = current[int(bit)]
ValueError: invalid literal for int() with base 10: 'TIME_ZONE'

During handling of the above exception, another exception occurred:

Traceback (most recent call last):
  File "E:\Education\GitHub Projects\PhDPortal\env\lib\site-packages\django\core\handlers\base.py", line 149, in get_response
    response = self.process_exception_by_middleware(e, request)
  File "E:\Education\GitHub Projects\PhDPortal\env\lib\site-packages\django\core\handlers\base.py", line 147, in get_response
    response = wrapped_callback(request, *callback_args, **callback_kwargs)
  File "E:\Education\GitHub Projects\PhDPortal\env\lib\site-packages\django\contrib\auth\decorators.py", line 23, in _wrapped_view
    return view_func(request, *args, **kwargs)
  File "E:\Education\GitHub Projects\PhDPortal\app\views.py", line 434, in user_notifications
    'unread_notifications': unread_notifications,
  File "E:\Education\GitHub Projects\PhDPortal\env\lib\site-packages\django\shortcuts.py", line 67, in render
    template_name, context, request=request, using=using)
  File "E:\Education\GitHub Projects\PhDPortal\env\lib\site-packages\django\template\loader.py", line 97, in render_to_string
    return template.render(context, request)
  File "E:\Education\GitHub Projects\PhDPortal\env\lib\site-packages\django\template\backends\django.py", line 95, in render
    return self.template.render(context)
  File "E:\Education\GitHub Projects\PhDPortal\env\lib\site-packages\django\template\base.py", line 206, in render
    return self._render(context)
  File "E:\Education\GitHub Projects\PhDPortal\env\lib\site-packages\django\template\base.py", line 197, in _render
    return self.nodelist.render(context)
  File "E:\Education\GitHub Projects\PhDPortal\env\lib\site-packages\django\template\base.py", line 988, in render
    bit = node.render_annotated(context)
  File "E:\Education\GitHub Projects\PhDPortal\env\lib\site-packages\django\template\base.py", line 955, in render_annotated
    return self.render(context)
  File "E:\Education\GitHub Projects\PhDPortal\env\lib\site-packages\django\template\loader_tags.py", line 173, in render
    return compiled_parent._render(context)
  File "E:\Education\GitHub Projects\PhDPortal\env\lib\site-packages\django\template\base.py", line 197, in _render
    return self.nodelist.render(context)
  File "E:\Education\GitHub Projects\PhDPortal\env\lib\site-packages\django\template\base.py", line 988, in render
    bit = node.render_annotated(context)
  File "E:\Education\GitHub Projects\PhDPortal\env\lib\site-packages\django\template\base.py", line 955, in render_annotated
    return self.render(context)
  File "E:\Education\GitHub Projects\PhDPortal\env\lib\site-packages\django\template\loader_tags.py", line 69, in render
    result = block.nodelist.render(context)
  File "E:\Education\GitHub Projects\PhDPortal\env\lib\site-packages\django\template\base.py", line 988, in render
    bit = node.render_annotated(context)
  File "E:\Education\GitHub Projects\PhDPortal\env\lib\site-packages\django\template\base.py", line 955, in render_annotated
    return self.render(context)
  File "E:\Education\GitHub Projects\PhDPortal\env\lib\site-packages\django\template\defaulttags.py", line 326, in render
    return nodelist.render(context)
  File "E:\Education\GitHub Projects\PhDPortal\env\lib\site-packages\django\template\base.py", line 988, in render
    bit = node.render_annotated(context)
  File "E:\Education\GitHub Projects\PhDPortal\env\lib\site-packages\django\template\base.py", line 955, in render_annotated
    return self.render(context)
  File "E:\Education\GitHub Projects\PhDPortal\env\lib\site-packages\django\template\defaulttags.py", line 220, in render
    nodelist.append(node.render_annotated(context))
  File "E:\Education\GitHub Projects\PhDPortal\env\lib\site-packages\django\template\base.py", line 955, in render_annotated
    return self.render(context)
  File "E:\Education\GitHub Projects\PhDPortal\env\lib\site-packages\django\template\base.py", line 1039, in render
    output = self.filter_expression.resolve(context)
  File "E:\Education\GitHub Projects\PhDPortal\env\lib\site-packages\django\template\base.py", line 726, in resolve
    arg_vals.append(arg.resolve(context))
  File "E:\Education\GitHub Projects\PhDPortal\env\lib\site-packages\django\template\base.py", line 846, in resolve
    value = self._resolve_lookup(context)
  File "E:\Education\GitHub Projects\PhDPortal\env\lib\site-packages\django\template\base.py", line 901, in _resolve_lookup
    (bit, current))  # missing attribute
django.template.base.VariableDoesNotExist: Failed lookup for key [TIME_ZONE] in "[{'True': True, 'False': False, 'None': None}, {}, {}, {'title': 'Notifications', 'layout_data': {'unread_notifications_count': 6, 'unread_notifications': [<Notification:  notification>, <Notification:  notification>, <Notification:  notification>]}, 'read_notifications': [<Notification:  notification>, <Notification:  notification>, <Notification:  notification>], 'unread_notifications': [<Notification:  notification>, <Notification:  notification>, <Notification:  notification>, <Notification:  notification>, <Notification:  notification>, <Notification:  notification>]}]"
2017-04-03 18:14:36 - ERROR - base:handle_uncaught_exception:284 - Internal Server Error: /user/notifications/
Traceback (most recent call last):
  File "E:\Education\GitHub Projects\PhDPortal\env\lib\site-packages\django\core\handlers\base.py", line 149, in get_response
    response = self.process_exception_by_middleware(e, request)
  File "E:\Education\GitHub Projects\PhDPortal\env\lib\site-packages\django\core\handlers\base.py", line 147, in get_response
    response = wrapped_callback(request, *callback_args, **callback_kwargs)
  File "E:\Education\GitHub Projects\PhDPortal\env\lib\site-packages\django\contrib\auth\decorators.py", line 23, in _wrapped_view
    return view_func(request, *args, **kwargs)
  File "E:\Education\GitHub Projects\PhDPortal\app\views.py", line 434, in user_notifications
    'unread_notifications': unread_notifications,
  File "E:\Education\GitHub Projects\PhDPortal\env\lib\site-packages\django\shortcuts.py", line 67, in render
    template_name, context, request=request, using=using)
  File "E:\Education\GitHub Projects\PhDPortal\env\lib\site-packages\django\template\loader.py", line 97, in render_to_string
    return template.render(context, request)
  File "E:\Education\GitHub Projects\PhDPortal\env\lib\site-packages\django\template\backends\django.py", line 95, in render
    return self.template.render(context)
  File "E:\Education\GitHub Projects\PhDPortal\env\lib\site-packages\django\template\base.py", line 206, in render
    return self._render(context)
  File "E:\Education\GitHub Projects\PhDPortal\env\lib\site-packages\django\template\base.py", line 197, in _render
    return self.nodelist.render(context)
  File "E:\Education\GitHub Projects\PhDPortal\env\lib\site-packages\django\template\base.py", line 988, in render
    bit = node.render_annotated(context)
  File "E:\Education\GitHub Projects\PhDPortal\env\lib\site-packages\django\template\base.py", line 955, in render_annotated
    return self.render(context)
  File "E:\Education\GitHub Projects\PhDPortal\env\lib\site-packages\django\template\loader_tags.py", line 173, in render
    return compiled_parent._render(context)
  File "E:\Education\GitHub Projects\PhDPortal\env\lib\site-packages\django\template\base.py", line 197, in _render
    return self.nodelist.render(context)
  File "E:\Education\GitHub Projects\PhDPortal\env\lib\site-packages\django\template\base.py", line 988, in render
    bit = node.render_annotated(context)
  File "E:\Education\GitHub Projects\PhDPortal\env\lib\site-packages\django\template\base.py", line 955, in render_annotated
    return self.render(context)
  File "E:\Education\GitHub Projects\PhDPortal\env\lib\site-packages\django\template\loader_tags.py", line 69, in render
    result = block.nodelist.render(context)
  File "E:\Education\GitHub Projects\PhDPortal\env\lib\site-packages\django\template\base.py", line 988, in render
    bit = node.render_annotated(context)
  File "E:\Education\GitHub Projects\PhDPortal\env\lib\site-packages\django\template\base.py", line 955, in render_annotated
    return self.render(context)
  File "E:\Education\GitHub Projects\PhDPortal\env\lib\site-packages\django\template\defaulttags.py", line 326, in render
    return nodelist.render(context)
  File "E:\Education\GitHub Projects\PhDPortal\env\lib\site-packages\django\template\base.py", line 988, in render
    bit = node.render_annotated(context)
  File "E:\Education\GitHub Projects\PhDPortal\env\lib\site-packages\django\template\base.py", line 955, in render_annotated
    return self.render(context)
  File "E:\Education\GitHub Projects\PhDPortal\env\lib\site-packages\django\template\defaulttags.py", line 220, in render
    nodelist.append(node.render_annotated(context))
  File "E:\Education\GitHub Projects\PhDPortal\env\lib\site-packages\django\template\base.py", line 955, in render_annotated
    return self.render(context)
  File "E:\Education\GitHub Projects\PhDPortal\env\lib\site-packages\django\templatetags\tz.py", line 113, in render
    with timezone.override(self.tz.resolve(context)):
  File "E:\Education\GitHub Projects\PhDPortal\env\lib\site-packages\django\utils\timezone.py", line 269, in __enter__
    activate(self.timezone)
  File "E:\Education\GitHub Projects\PhDPortal\env\lib\site-packages\django\utils\timezone.py", line 234, in activate
    _active.value = pytz.timezone(timezone)
  File "E:\Education\GitHub Projects\PhDPortal\env\lib\site-packages\pytz\__init__.py", line 181, in timezone
    raise UnknownTimeZoneError(zone)
pytz.exceptions.UnknownTimeZoneError: ''
2017-04-03 18:22:44 - ERROR - base:handle_uncaught_exception:284 - Internal Server Error: /user/notifications/
Traceback (most recent call last):
  File "E:\Education\GitHub Projects\PhDPortal\env\lib\site-packages\django\core\handlers\base.py", line 149, in get_response
    response = self.process_exception_by_middleware(e, request)
  File "E:\Education\GitHub Projects\PhDPortal\env\lib\site-packages\django\core\handlers\base.py", line 147, in get_response
    response = wrapped_callback(request, *callback_args, **callback_kwargs)
  File "E:\Education\GitHub Projects\PhDPortal\env\lib\site-packages\django\contrib\auth\decorators.py", line 23, in _wrapped_view
    return view_func(request, *args, **kwargs)
  File "E:\Education\GitHub Projects\PhDPortal\app\views.py", line 434, in user_notifications
    'unread_notifications': unread_notifications,
  File "E:\Education\GitHub Projects\PhDPortal\env\lib\site-packages\django\shortcuts.py", line 67, in render
    template_name, context, request=request, using=using)
  File "E:\Education\GitHub Projects\PhDPortal\env\lib\site-packages\django\template\loader.py", line 97, in render_to_string
    return template.render(context, request)
  File "E:\Education\GitHub Projects\PhDPortal\env\lib\site-packages\django\template\backends\django.py", line 95, in render
    return self.template.render(context)
  File "E:\Education\GitHub Projects\PhDPortal\env\lib\site-packages\django\template\base.py", line 206, in render
    return self._render(context)
  File "E:\Education\GitHub Projects\PhDPortal\env\lib\site-packages\django\template\base.py", line 197, in _render
    return self.nodelist.render(context)
  File "E:\Education\GitHub Projects\PhDPortal\env\lib\site-packages\django\template\base.py", line 988, in render
    bit = node.render_annotated(context)
  File "E:\Education\GitHub Projects\PhDPortal\env\lib\site-packages\django\template\base.py", line 955, in render_annotated
    return self.render(context)
  File "E:\Education\GitHub Projects\PhDPortal\env\lib\site-packages\django\template\loader_tags.py", line 173, in render
    return compiled_parent._render(context)
  File "E:\Education\GitHub Projects\PhDPortal\env\lib\site-packages\django\template\base.py", line 197, in _render
    return self.nodelist.render(context)
  File "E:\Education\GitHub Projects\PhDPortal\env\lib\site-packages\django\template\base.py", line 988, in render
    bit = node.render_annotated(context)
  File "E:\Education\GitHub Projects\PhDPortal\env\lib\site-packages\django\template\base.py", line 955, in render_annotated
    return self.render(context)
  File "E:\Education\GitHub Projects\PhDPortal\env\lib\site-packages\django\template\loader_tags.py", line 69, in render
    result = block.nodelist.render(context)
  File "E:\Education\GitHub Projects\PhDPortal\env\lib\site-packages\django\template\base.py", line 988, in render
    bit = node.render_annotated(context)
  File "E:\Education\GitHub Projects\PhDPortal\env\lib\site-packages\django\template\base.py", line 955, in render_annotated
    return self.render(context)
  File "E:\Education\GitHub Projects\PhDPortal\env\lib\site-packages\django\template\defaulttags.py", line 326, in render
    return nodelist.render(context)
  File "E:\Education\GitHub Projects\PhDPortal\env\lib\site-packages\django\template\base.py", line 988, in render
    bit = node.render_annotated(context)
  File "E:\Education\GitHub Projects\PhDPortal\env\lib\site-packages\django\template\base.py", line 955, in render_annotated
    return self.render(context)
  File "E:\Education\GitHub Projects\PhDPortal\env\lib\site-packages\django\template\defaulttags.py", line 220, in render
    nodelist.append(node.render_annotated(context))
  File "E:\Education\GitHub Projects\PhDPortal\env\lib\site-packages\django\template\base.py", line 955, in render_annotated
    return self.render(context)
  File "E:\Education\GitHub Projects\PhDPortal\env\lib\site-packages\django\templatetags\tz.py", line 113, in render
    with timezone.override(self.tz.resolve(context)):
  File "E:\Education\GitHub Projects\PhDPortal\env\lib\site-packages\django\utils\timezone.py", line 269, in __enter__
    activate(self.timezone)
  File "E:\Education\GitHub Projects\PhDPortal\env\lib\site-packages\django\utils\timezone.py", line 234, in activate
    _active.value = pytz.timezone(timezone)
  File "E:\Education\GitHub Projects\PhDPortal\env\lib\site-packages\pytz\__init__.py", line 181, in timezone
    raise UnknownTimeZoneError(zone)
pytz.exceptions.UnknownTimeZoneError: ''
2017-04-03 18:23:03 - ERROR - base:handle_uncaught_exception:284 - Internal Server Error: /user/notifications/
Traceback (most recent call last):
  File "E:\Education\GitHub Projects\PhDPortal\env\lib\site-packages\django\core\handlers\base.py", line 149, in get_response
    response = self.process_exception_by_middleware(e, request)
  File "E:\Education\GitHub Projects\PhDPortal\env\lib\site-packages\django\core\handlers\base.py", line 147, in get_response
    response = wrapped_callback(request, *callback_args, **callback_kwargs)
  File "E:\Education\GitHub Projects\PhDPortal\env\lib\site-packages\django\contrib\auth\decorators.py", line 23, in _wrapped_view
    return view_func(request, *args, **kwargs)
  File "E:\Education\GitHub Projects\PhDPortal\app\views.py", line 434, in user_notifications
    'unread_notifications': unread_notifications,
  File "E:\Education\GitHub Projects\PhDPortal\env\lib\site-packages\django\shortcuts.py", line 67, in render
    template_name, context, request=request, using=using)
  File "E:\Education\GitHub Projects\PhDPortal\env\lib\site-packages\django\template\loader.py", line 97, in render_to_string
    return template.render(context, request)
  File "E:\Education\GitHub Projects\PhDPortal\env\lib\site-packages\django\template\backends\django.py", line 95, in render
    return self.template.render(context)
  File "E:\Education\GitHub Projects\PhDPortal\env\lib\site-packages\django\template\base.py", line 206, in render
    return self._render(context)
  File "E:\Education\GitHub Projects\PhDPortal\env\lib\site-packages\django\template\base.py", line 197, in _render
    return self.nodelist.render(context)
  File "E:\Education\GitHub Projects\PhDPortal\env\lib\site-packages\django\template\base.py", line 988, in render
    bit = node.render_annotated(context)
  File "E:\Education\GitHub Projects\PhDPortal\env\lib\site-packages\django\template\base.py", line 955, in render_annotated
    return self.render(context)
  File "E:\Education\GitHub Projects\PhDPortal\env\lib\site-packages\django\template\loader_tags.py", line 173, in render
    return compiled_parent._render(context)
  File "E:\Education\GitHub Projects\PhDPortal\env\lib\site-packages\django\template\base.py", line 197, in _render
    return self.nodelist.render(context)
  File "E:\Education\GitHub Projects\PhDPortal\env\lib\site-packages\django\template\base.py", line 988, in render
    bit = node.render_annotated(context)
  File "E:\Education\GitHub Projects\PhDPortal\env\lib\site-packages\django\template\base.py", line 955, in render_annotated
    return self.render(context)
  File "E:\Education\GitHub Projects\PhDPortal\env\lib\site-packages\django\template\loader_tags.py", line 69, in render
    result = block.nodelist.render(context)
  File "E:\Education\GitHub Projects\PhDPortal\env\lib\site-packages\django\template\base.py", line 988, in render
    bit = node.render_annotated(context)
  File "E:\Education\GitHub Projects\PhDPortal\env\lib\site-packages\django\template\base.py", line 955, in render_annotated
    return self.render(context)
  File "E:\Education\GitHub Projects\PhDPortal\env\lib\site-packages\django\template\defaulttags.py", line 326, in render
    return nodelist.render(context)
  File "E:\Education\GitHub Projects\PhDPortal\env\lib\site-packages\django\template\base.py", line 988, in render
    bit = node.render_annotated(context)
  File "E:\Education\GitHub Projects\PhDPortal\env\lib\site-packages\django\template\base.py", line 955, in render_annotated
    return self.render(context)
  File "E:\Education\GitHub Projects\PhDPortal\env\lib\site-packages\django\template\defaulttags.py", line 220, in render
    nodelist.append(node.render_annotated(context))
  File "E:\Education\GitHub Projects\PhDPortal\env\lib\site-packages\django\template\base.py", line 955, in render_annotated
    return self.render(context)
  File "E:\Education\GitHub Projects\PhDPortal\env\lib\site-packages\django\templatetags\tz.py", line 113, in render
    with timezone.override(self.tz.resolve(context)):
  File "E:\Education\GitHub Projects\PhDPortal\env\lib\site-packages\django\utils\timezone.py", line 269, in __enter__
    activate(self.timezone)
  File "E:\Education\GitHub Projects\PhDPortal\env\lib\site-packages\django\utils\timezone.py", line 234, in activate
    _active.value = pytz.timezone(timezone)
  File "E:\Education\GitHub Projects\PhDPortal\env\lib\site-packages\pytz\__init__.py", line 181, in timezone
    raise UnknownTimeZoneError(zone)
pytz.exceptions.UnknownTimeZoneError: ''
2017-04-03 18:26:03 - ERROR - base:handle_uncaught_exception:284 - Internal Server Error: /user/notifications/
Traceback (most recent call last):
  File "E:\Education\GitHub Projects\PhDPortal\env\lib\site-packages\django\core\handlers\base.py", line 149, in get_response
    response = self.process_exception_by_middleware(e, request)
  File "E:\Education\GitHub Projects\PhDPortal\env\lib\site-packages\django\core\handlers\base.py", line 147, in get_response
    response = wrapped_callback(request, *callback_args, **callback_kwargs)
  File "E:\Education\GitHub Projects\PhDPortal\env\lib\site-packages\django\contrib\auth\decorators.py", line 23, in _wrapped_view
    return view_func(request, *args, **kwargs)
  File "E:\Education\GitHub Projects\PhDPortal\app\views.py", line 436, in user_notifications
    'TZ' : timezone.get_current_timezone(),
NameError: name 'timezone' is not defined
2017-04-03 18:26:33 - ERROR - base:handle_uncaught_exception:284 - Internal Server Error: /user/notifications/
Traceback (most recent call last):
  File "E:\Education\GitHub Projects\PhDPortal\env\lib\site-packages\django\core\handlers\base.py", line 149, in get_response
    response = self.process_exception_by_middleware(e, request)
  File "E:\Education\GitHub Projects\PhDPortal\env\lib\site-packages\django\core\handlers\base.py", line 147, in get_response
    response = wrapped_callback(request, *callback_args, **callback_kwargs)
  File "E:\Education\GitHub Projects\PhDPortal\env\lib\site-packages\django\contrib\auth\decorators.py", line 23, in _wrapped_view
    return view_func(request, *args, **kwargs)
  File "E:\Education\GitHub Projects\PhDPortal\app\views.py", line 436, in user_notifications
    'TZ' : timezone.get_current_timezone(),
NameError: name 'timezone' is not defined
2017-04-03 18:33:10 - ERROR - base:handle_uncaught_exception:284 - Internal Server Error: /user/notifications/
Traceback (most recent call last):
  File "E:\Education\GitHub Projects\PhDPortal\env\lib\site-packages\django\core\handlers\base.py", line 149, in get_response
    response = self.process_exception_by_middleware(e, request)
  File "E:\Education\GitHub Projects\PhDPortal\env\lib\site-packages\django\core\handlers\base.py", line 147, in get_response
    response = wrapped_callback(request, *callback_args, **callback_kwargs)
  File "E:\Education\GitHub Projects\PhDPortal\env\lib\site-packages\django\contrib\auth\decorators.py", line 23, in _wrapped_view
    return view_func(request, *args, **kwargs)
  File "E:\Education\GitHub Projects\PhDPortal\app\views.py", line 428, in user_notifications
    activate(settings.TIME_ZONE)
NameError: name 'settings' is not defined
2017-04-03 19:15:06 - ERROR - base:handle_uncaught_exception:284 - Internal Server Error: /user/notifications/
Traceback (most recent call last):
  File "E:\Education\GitHub Projects\PhDPortal\env\lib\site-packages\django\core\handlers\base.py", line 149, in get_response
    response = self.process_exception_by_middleware(e, request)
  File "E:\Education\GitHub Projects\PhDPortal\env\lib\site-packages\django\core\handlers\base.py", line 147, in get_response
    response = wrapped_callback(request, *callback_args, **callback_kwargs)
  File "E:\Education\GitHub Projects\PhDPortal\env\lib\site-packages\django\contrib\auth\decorators.py", line 23, in _wrapped_view
    return view_func(request, *args, **kwargs)
  File "E:\Education\GitHub Projects\PhDPortal\app\views.py", line 428, in user_notifications
    date = datetime.now(get_localzone())
NameError: name 'datetime' is not defined
2017-04-03 20:31:20 - INFO - views:login:352 - User ash successfully authenticated
2017-04-03 20:32:48 - INFO - views:login:352 - User angelina successfully authenticated
2017-04-03 20:33:38 - INFO - views:login:352 - User anshul successfully authenticated
2017-04-03 20:34:00 - INFO - views:login:352 - User ash successfully authenticated
2017-04-18 11:37:20 - INFO - views:login:390 - User janit successfully authenticated
2017-04-18 11:37:26 - ERROR - base:handle_uncaught_exception:284 - Internal Server Error: /referee/change-password/
Traceback (most recent call last):
  File "C:\Python34\lib\site-packages\django\core\handlers\base.py", line 149, in get_response
    response = self.process_exception_by_middleware(e, request)
  File "C:\Python34\lib\site-packages\django\core\handlers\base.py", line 147, in get_response
    response = wrapped_callback(request, *callback_args, **callback_kwargs)
  File "C:\Python34\lib\site-packages\django\contrib\auth\decorators.py", line 23, in _wrapped_view
    return view_func(request, *args, **kwargs)
  File "D:\Github Projects\PhDPortal\app\referee_views.py", line 37, in referee_change_password
    user_details = _get_user_type_object(user)
NameError: name '_get_user_type_object' is not defined
2017-04-18 12:51:20 - INFO - views:logout:412 - User janit successfully logged out
2017-04-18 12:51:32 - INFO - views:login:390 - User anshul successfully authenticated
2017-04-18 12:52:46 - INFO - views:logout:412 - User anshul successfully logged out
2017-04-18 12:53:15 - INFO - views:login:390 - User anshul successfully authenticated
2017-04-18 12:53:39 - INFO - views:logout:412 - User anshul successfully logged out
2017-04-18 12:53:53 - INFO - views:login:390 - User ranjana successfully authenticated
2017-04-18 12:54:11 - INFO - views:logout:412 - User ranjana successfully logged out
2017-04-18 13:38:00 - INFO - views:login:390 - User anshul successfully authenticated
2017-04-18 13:45:09 - INFO - views:login:390 - User anshul successfully authenticated
2017-04-18 13:56:26 - INFO - views:logout:412 - User anshul successfully logged out
2017-04-18 13:56:37 - INFO - views:login:390 - User janit successfully authenticated
2017-04-18 14:25:40 - ERROR - base:handle_uncaught_exception:284 - Internal Server Error: /referee/change-password/
Traceback (most recent call last):
  File "C:\Python34\lib\site-packages\django\core\handlers\base.py", line 149, in get_response
    response = self.process_exception_by_middleware(e, request)
  File "C:\Python34\lib\site-packages\django\core\handlers\base.py", line 147, in get_response
    response = wrapped_callback(request, *callback_args, **callback_kwargs)
  File "C:\Python34\lib\site-packages\django\contrib\auth\decorators.py", line 23, in _wrapped_view
    return view_func(request, *args, **kwargs)
  File "D:\Github Projects\PhDPortal\app\referee_views.py", line 45, in referee_change_password
    user = _get_user_type_object(user)  # temporary fix
NameError: name '_get_user_type_object' is not defined
2017-04-18 14:26:30 - ERROR - base:handle_uncaught_exception:284 - Internal Server Error: /referee/change-password/
Traceback (most recent call last):
  File "C:\Python34\lib\site-packages\django\utils\datastructures.py", line 83, in __getitem__
    list_ = super(MultiValueDict, self).__getitem__(key)
KeyError: 'new-password'

During handling of the above exception, another exception occurred:

Traceback (most recent call last):
  File "C:\Python34\lib\site-packages\django\core\handlers\base.py", line 149, in get_response
    response = self.process_exception_by_middleware(e, request)
  File "C:\Python34\lib\site-packages\django\core\handlers\base.py", line 147, in get_response
    response = wrapped_callback(request, *callback_args, **callback_kwargs)
  File "C:\Python34\lib\site-packages\django\contrib\auth\decorators.py", line 23, in _wrapped_view
    return view_func(request, *args, **kwargs)
  File "D:\Github Projects\PhDPortal\app\referee_views.py", line 47, in referee_change_password
    new = request.POST['new-password']
  File "C:\Python34\lib\site-packages\django\utils\datastructures.py", line 85, in __getitem__
    raise MultiValueDictKeyError(repr(key))
django.utils.datastructures.MultiValueDictKeyError: "'new-password'"
2017-04-18 14:28:47 - ERROR - base:handle_uncaught_exception:284 - Internal Server Error: /referee/change-password/
Traceback (most recent call last):
  File "C:\Python34\lib\site-packages\django\utils\datastructures.py", line 83, in __getitem__
    list_ = super(MultiValueDict, self).__getitem__(key)
KeyError: 'new-password'

During handling of the above exception, another exception occurred:

Traceback (most recent call last):
  File "C:\Python34\lib\site-packages\django\core\handlers\base.py", line 149, in get_response
    response = self.process_exception_by_middleware(e, request)
  File "C:\Python34\lib\site-packages\django\core\handlers\base.py", line 147, in get_response
    response = wrapped_callback(request, *callback_args, **callback_kwargs)
  File "C:\Python34\lib\site-packages\django\contrib\auth\decorators.py", line 23, in _wrapped_view
    return view_func(request, *args, **kwargs)
  File "D:\Github Projects\PhDPortal\app\referee_views.py", line 47, in referee_change_password
    new = request.POST['new-password']
  File "C:\Python34\lib\site-packages\django\utils\datastructures.py", line 85, in __getitem__
    raise MultiValueDictKeyError(repr(key))
django.utils.datastructures.MultiValueDictKeyError: "'new-password'"
2017-04-18 14:29:46 - INFO - views:logout:412 - User janit successfully logged out
2017-04-18 14:29:59 - INFO - views:login:390 - User janit successfully authenticated
2017-04-18 15:54:59 - INFO - views:login:390 - User pavan successfully authenticated
2017-04-18 18:10:53 - INFO - views:login:390 - User pavan successfully authenticated
2017-04-18 18:12:47 - ERROR - base:handle_uncaught_exception:284 - Internal Server Error: /guide/add/referee/
Traceback (most recent call last):
  File "C:\Python34\lib\site-packages\django\core\handlers\base.py", line 149, in get_response
    response = self.process_exception_by_middleware(e, request)
  File "C:\Python34\lib\site-packages\django\core\handlers\base.py", line 147, in get_response
    response = wrapped_callback(request, *callback_args, **callback_kwargs)
  File "D:\Github Projects\PhDPortal\app\guide_views.py", line 36, in guide_add_referee
    'layout_data' : get_layout_data(request),
  File "C:\Python34\lib\site-packages\django\shortcuts.py", line 67, in render
    template_name, context, request=request, using=using)
  File "C:\Python34\lib\site-packages\django\template\loader.py", line 96, in render_to_string
    template = get_template(template_name, using=using)
  File "C:\Python34\lib\site-packages\django\template\loader.py", line 43, in get_template
    raise TemplateDoesNotExist(template_name, chain=chain)
django.template.exceptions.TemplateDoesNotExist: app/guide/add/referee.html
2017-04-18 18:38:32 - INFO - views:login:390 - User pavan successfully authenticated
2017-04-18 18:39:43 - ERROR - base:handle_uncaught_exception:284 - Internal Server Error: /guide/add/referee/
Traceback (most recent call last):
  File "C:\Python34\lib\site-packages\django\utils\datastructures.py", line 83, in __getitem__
    list_ = super(MultiValueDict, self).__getitem__(key)
KeyError: 'username'

During handling of the above exception, another exception occurred:

Traceback (most recent call last):
  File "C:\Python34\lib\site-packages\django\core\handlers\base.py", line 149, in get_response
    response = self.process_exception_by_middleware(e, request)
  File "C:\Python34\lib\site-packages\django\core\handlers\base.py", line 147, in get_response
    response = wrapped_callback(request, *callback_args, **callback_kwargs)
  File "D:\Github Projects\PhDPortal\app\guide_views.py", line 54, in guide_add_referee
    username = request.POST['username']
  File "C:\Python34\lib\site-packages\django\utils\datastructures.py", line 85, in __getitem__
    raise MultiValueDictKeyError(repr(key))
django.utils.datastructures.MultiValueDictKeyError: "'username'"
2017-04-18 18:43:32 - ERROR - base:handle_uncaught_exception:284 - Internal Server Error: /guide/add/referee/
Traceback (most recent call last):
  File "C:\Python34\lib\site-packages\django\utils\datastructures.py", line 83, in __getitem__
    list_ = super(MultiValueDict, self).__getitem__(key)
KeyError: 'username'

During handling of the above exception, another exception occurred:

Traceback (most recent call last):
  File "C:\Python34\lib\site-packages\django\core\handlers\base.py", line 149, in get_response
    response = self.process_exception_by_middleware(e, request)
  File "C:\Python34\lib\site-packages\django\core\handlers\base.py", line 147, in get_response
    response = wrapped_callback(request, *callback_args, **callback_kwargs)
  File "D:\Github Projects\PhDPortal\app\guide_views.py", line 54, in guide_add_referee
    username = request.POST['username']
  File "C:\Python34\lib\site-packages\django\utils\datastructures.py", line 85, in __getitem__
    raise MultiValueDictKeyError(repr(key))
django.utils.datastructures.MultiValueDictKeyError: "'username'"
2017-04-18 19:18:21 - INFO - views:login:390 - User pavan successfully authenticated
2017-04-18 19:58:40 - INFO - views:logout:412 - User pavan successfully logged out
2017-04-18 19:58:47 - INFO - views:login:390 - User pavan successfully authenticated
2017-04-18 20:05:29 - ERROR - base:handle_uncaught_exception:284 - Internal Server Error: /guide/add/referee/
Traceback (most recent call last):
  File "C:\Python34\lib\site-packages\django\core\handlers\base.py", line 158, in get_response
    % (callback.__module__, view_name))
ValueError: The view app.guide_views.guide_add_referee didn't return an HttpResponse object. It returned None instead.
2017-04-18 20:06:38 - ERROR - base:handle_uncaught_exception:284 - Internal Server Error: /guide/add/referee/
Traceback (most recent call last):
  File "C:\Python34\lib\site-packages\django\db\backends\utils.py", line 64, in execute
    return self.cursor.execute(sql, params)
  File "C:\Python34\lib\site-packages\django\db\backends\sqlite3\base.py", line 323, in execute
    return Database.Cursor.execute(self, query, params)
sqlite3.OperationalError: table app_sample has no column named phone_number

The above exception was the direct cause of the following exception:

Traceback (most recent call last):
  File "C:\Python34\lib\site-packages\django\core\handlers\base.py", line 149, in get_response
    response = self.process_exception_by_middleware(e, request)
  File "C:\Python34\lib\site-packages\django\core\handlers\base.py", line 147, in get_response
    response = wrapped_callback(request, *callback_args, **callback_kwargs)
  File "D:\Github Projects\PhDPortal\app\guide_views.py", line 38, in guide_add_referee
    form.save()
  File "C:\Python34\lib\site-packages\django\forms\models.py", line 451, in save
    self.instance.save()
  File "C:\Python34\lib\site-packages\django\db\models\base.py", line 700, in save
    force_update=force_update, update_fields=update_fields)
  File "C:\Python34\lib\site-packages\django\db\models\base.py", line 728, in save_base
    updated = self._save_table(raw, cls, force_insert, force_update, using, update_fields)
  File "C:\Python34\lib\site-packages\django\db\models\base.py", line 812, in _save_table
    result = self._do_insert(cls._base_manager, using, fields, update_pk, raw)
  File "C:\Python34\lib\site-packages\django\db\models\base.py", line 851, in _do_insert
    using=using, raw=raw)
  File "C:\Python34\lib\site-packages\django\db\models\manager.py", line 122, in manager_method
    return getattr(self.get_queryset(), name)(*args, **kwargs)
  File "C:\Python34\lib\site-packages\django\db\models\query.py", line 1039, in _insert
    return query.get_compiler(using=using).execute_sql(return_id)
  File "C:\Python34\lib\site-packages\django\db\models\sql\compiler.py", line 1064, in execute_sql
    cursor.execute(sql, params)
  File "C:\Python34\lib\site-packages\django\db\backends\utils.py", line 79, in execute
    return super(CursorDebugWrapper, self).execute(sql, params)
  File "C:\Python34\lib\site-packages\django\db\backends\utils.py", line 64, in execute
    return self.cursor.execute(sql, params)
  File "C:\Python34\lib\site-packages\django\db\utils.py", line 95, in __exit__
    six.reraise(dj_exc_type, dj_exc_value, traceback)
  File "C:\Python34\lib\site-packages\django\utils\six.py", line 685, in reraise
    raise value.with_traceback(tb)
  File "C:\Python34\lib\site-packages\django\db\backends\utils.py", line 64, in execute
    return self.cursor.execute(sql, params)
  File "C:\Python34\lib\site-packages\django\db\backends\sqlite3\base.py", line 323, in execute
    return Database.Cursor.execute(self, query, params)
django.db.utils.OperationalError: table app_sample has no column named phone_number
2017-04-18 20:29:24 - INFO - views:login:390 - User pavan successfully authenticated
2017-04-18 20:45:02 - INFO - views:logout:412 - User pavan successfully logged out
2017-04-18 20:45:09 - INFO - views:login:390 - User pavan successfully authenticated
2017-04-18 20:50:12 - ERROR - base:handle_uncaught_exception:284 - Internal Server Error: /guide/add/referee/
Traceback (most recent call last):
  File "C:\Python34\lib\site-packages\django\template\base.py", line 506, in parse
    compile_func = self.tags[command]
KeyError: 'endif'

During handling of the above exception, another exception occurred:

Traceback (most recent call last):
  File "C:\Python34\lib\site-packages\django\core\handlers\base.py", line 149, in get_response
    response = self.process_exception_by_middleware(e, request)
  File "C:\Python34\lib\site-packages\django\core\handlers\base.py", line 147, in get_response
    response = wrapped_callback(request, *callback_args, **callback_kwargs)
  File "D:\Github Projects\PhDPortal\app\guide_views.py", line 56, in guide_add_referee
    'layout_data': get_layout_data(request)
  File "C:\Python34\lib\site-packages\django\shortcuts.py", line 67, in render
    template_name, context, request=request, using=using)
  File "C:\Python34\lib\site-packages\django\template\loader.py", line 96, in render_to_string
    template = get_template(template_name, using=using)
  File "C:\Python34\lib\site-packages\django\template\loader.py", line 32, in get_template
    return engine.get_template(template_name, dirs)
  File "C:\Python34\lib\site-packages\django\template\backends\django.py", line 40, in get_template
    return Template(self.engine.get_template(template_name, dirs), self)
  File "C:\Python34\lib\site-packages\django\template\engine.py", line 190, in get_template
    template, origin = self.find_template(template_name, dirs)
  File "C:\Python34\lib\site-packages\django\template\engine.py", line 157, in find_template
    name, template_dirs=dirs, skip=skip,
  File "C:\Python34\lib\site-packages\django\template\loaders\base.py", line 46, in get_template
    contents, origin, origin.template_name, self.engine,
  File "C:\Python34\lib\site-packages\django\template\base.py", line 189, in __init__
    self.nodelist = self.compile_nodelist()
  File "C:\Python34\lib\site-packages\django\template\base.py", line 230, in compile_nodelist
    return parser.parse()
  File "C:\Python34\lib\site-packages\django\template\base.py", line 514, in parse
    raise self.error(token, e)
  File "C:\Python34\lib\site-packages\django\template\base.py", line 512, in parse
    compiled_result = compile_func(self, token)
  File "C:\Python34\lib\site-packages\django\template\loader_tags.py", line 267, in do_extends
    nodelist = parser.parse()
  File "C:\Python34\lib\site-packages\django\template\base.py", line 514, in parse
    raise self.error(token, e)
  File "C:\Python34\lib\site-packages\django\template\base.py", line 512, in parse
    compiled_result = compile_func(self, token)
  File "C:\Python34\lib\site-packages\django\template\loader_tags.py", line 241, in do_block
    nodelist = parser.parse(('endblock',))
  File "C:\Python34\lib\site-packages\django\template\base.py", line 514, in parse
    raise self.error(token, e)
  File "C:\Python34\lib\site-packages\django\template\base.py", line 512, in parse
    compiled_result = compile_func(self, token)
  File "C:\Python34\lib\site-packages\django\template\defaulttags.py", line 886, in do_for
    nodelist_loop = parser.parse(('empty', 'endfor',))
  File "C:\Python34\lib\site-packages\django\template\base.py", line 508, in parse
    self.invalid_block_tag(token, command, parse_until)
  File "C:\Python34\lib\site-packages\django\template\base.py", line 562, in invalid_block_tag
    get_text_list(["'%s'" % p for p in parse_until]),
django.template.exceptions.TemplateSyntaxError: Invalid block tag on line 27: 'endif', expected 'empty' or 'endfor'. Did you forget to register or load this tag?
2017-04-19 01:02:28 - ERROR - base:handle_uncaught_exception:284 - Internal Server Error: /guide/add/referee/
Traceback (most recent call last):
  File "C:\Python34\lib\site-packages\django\core\handlers\base.py", line 149, in get_response
    response = self.process_exception_by_middleware(e, request)
  File "C:\Python34\lib\site-packages\django\core\handlers\base.py", line 147, in get_response
    response = wrapped_callback(request, *callback_args, **callback_kwargs)
  File "D:\Github Projects\PhDPortal\app\guide_views.py", line 41, in guide_add_referee
    referee_form.save(user)
TypeError: save() takes 1 positional argument but 2 were given
2017-04-19 01:09:38 - ERROR - base:handle_uncaught_exception:284 - Internal Server Error: /guide/add/referee/
Traceback (most recent call last):
  File "C:\Python34\lib\site-packages\django\db\backends\utils.py", line 64, in execute
    return self.cursor.execute(sql, params)
  File "C:\Python34\lib\site-packages\django\db\backends\sqlite3\base.py", line 323, in execute
    return Database.Cursor.execute(self, query, params)
sqlite3.OperationalError: database is locked

The above exception was the direct cause of the following exception:

Traceback (most recent call last):
  File "C:\Python34\lib\site-packages\django\core\handlers\base.py", line 149, in get_response
    response = self.process_exception_by_middleware(e, request)
  File "C:\Python34\lib\site-packages\django\core\handlers\base.py", line 147, in get_response
    response = wrapped_callback(request, *callback_args, **callback_kwargs)
  File "D:\Github Projects\PhDPortal\app\guide_views.py", line 45, in guide_add_referee
    new_user.save()
  File "C:\Python34\lib\site-packages\django\contrib\auth\base_user.py", line 74, in save
    super(AbstractBaseUser, self).save(*args, **kwargs)
  File "C:\Python34\lib\site-packages\django\db\models\base.py", line 700, in save
    force_update=force_update, update_fields=update_fields)
  File "C:\Python34\lib\site-packages\django\db\models\base.py", line 728, in save_base
    updated = self._save_table(raw, cls, force_insert, force_update, using, update_fields)
  File "C:\Python34\lib\site-packages\django\db\models\base.py", line 812, in _save_table
    result = self._do_insert(cls._base_manager, using, fields, update_pk, raw)
  File "C:\Python34\lib\site-packages\django\db\models\base.py", line 851, in _do_insert
    using=using, raw=raw)
  File "C:\Python34\lib\site-packages\django\db\models\manager.py", line 122, in manager_method
    return getattr(self.get_queryset(), name)(*args, **kwargs)
  File "C:\Python34\lib\site-packages\django\db\models\query.py", line 1039, in _insert
    return query.get_compiler(using=using).execute_sql(return_id)
  File "C:\Python34\lib\site-packages\django\db\models\sql\compiler.py", line 1064, in execute_sql
    cursor.execute(sql, params)
  File "C:\Python34\lib\site-packages\django\db\backends\utils.py", line 79, in execute
    return super(CursorDebugWrapper, self).execute(sql, params)
  File "C:\Python34\lib\site-packages\django\db\backends\utils.py", line 64, in execute
    return self.cursor.execute(sql, params)
  File "C:\Python34\lib\site-packages\django\db\utils.py", line 95, in __exit__
    six.reraise(dj_exc_type, dj_exc_value, traceback)
  File "C:\Python34\lib\site-packages\django\utils\six.py", line 685, in reraise
    raise value.with_traceback(tb)
  File "C:\Python34\lib\site-packages\django\db\backends\utils.py", line 64, in execute
    return self.cursor.execute(sql, params)
  File "C:\Python34\lib\site-packages\django\db\backends\sqlite3\base.py", line 323, in execute
    return Database.Cursor.execute(self, query, params)
django.db.utils.OperationalError: database is locked
2017-04-19 01:24:14 - ERROR - base:handle_uncaught_exception:284 - Internal Server Error: /guide/add/referee/
Traceback (most recent call last):
  File "C:\Python34\lib\site-packages\django\core\handlers\base.py", line 149, in get_response
    response = self.process_exception_by_middleware(e, request)
  File "C:\Python34\lib\site-packages\django\core\handlers\base.py", line 147, in get_response
    response = wrapped_callback(request, *callback_args, **callback_kwargs)
  File "D:\Github Projects\PhDPortal\app\guide_views.py", line 41, in guide_add_referee
    referee_form.save(new_user)
TypeError: save() takes 1 positional argument but 2 were given
2017-04-19 01:26:57 - ERROR - base:handle_uncaught_exception:284 - Internal Server Error: /guide/add/referee/
Traceback (most recent call last):
  File "C:\Python34\lib\site-packages\django\core\handlers\base.py", line 149, in get_response
    response = self.process_exception_by_middleware(e, request)
  File "C:\Python34\lib\site-packages\django\core\handlers\base.py", line 147, in get_response
    response = wrapped_callback(request, *callback_args, **callback_kwargs)
  File "D:\Github Projects\PhDPortal\app\guide_views.py", line 41, in guide_add_referee
    referee_form.save(new_user)
TypeError: save() takes 1 positional argument but 2 were given
2017-04-19 01:30:34 - ERROR - base:handle_uncaught_exception:284 - Internal Server Error: /guide/add/referee/
Traceback (most recent call last):
  File "C:\Python34\lib\site-packages\django\core\handlers\base.py", line 149, in get_response
    response = self.process_exception_by_middleware(e, request)
  File "C:\Python34\lib\site-packages\django\core\handlers\base.py", line 147, in get_response
    response = wrapped_callback(request, *callback_args, **callback_kwargs)
  File "D:\Github Projects\PhDPortal\app\guide_views.py", line 41, in guide_add_referee
    referee_form.save(new_user)
  File "D:\Github Projects\PhDPortal\app\forms.py", line 62, in save
    referee = Referee(type=self.cleaned_data['type'], designation=self.cleaned_data['designation'], website = self.cleaned_data['website'], university = self.cleaned_data['university'], user = kwargs.pop('new_user'))
KeyError: 'new_user'
2017-04-19 02:03:51 - ERROR - base:handle_uncaught_exception:284 - Internal Server Error: /guide/add/referee/
Traceback (most recent call last):
  File "C:\Python34\lib\site-packages\django\core\handlers\base.py", line 149, in get_response
    response = self.process_exception_by_middleware(e, request)
  File "C:\Python34\lib\site-packages\django\core\handlers\base.py", line 147, in get_response
    response = wrapped_callback(request, *callback_args, **callback_kwargs)
  File "D:\Github Projects\PhDPortal\app\guide_views.py", line 57, in guide_add_referee
    'dict' :dict,
UnboundLocalError: local variable 'dict' referenced before assignment
2017-04-19 02:04:47 - ERROR - base:handle_uncaught_exception:284 - Internal Server Error: /guide/add/referee/
Traceback (most recent call last):
  File "C:\Python34\lib\site-packages\django\template\smartif.py", line 177, in translate_token
    op = OPERATORS[token]
KeyError: '==='

During handling of the above exception, another exception occurred:

Traceback (most recent call last):
  File "C:\Python34\lib\site-packages\django\core\handlers\base.py", line 149, in get_response
    response = self.process_exception_by_middleware(e, request)
  File "C:\Python34\lib\site-packages\django\core\handlers\base.py", line 147, in get_response
    response = wrapped_callback(request, *callback_args, **callback_kwargs)
  File "D:\Github Projects\PhDPortal\app\guide_views.py", line 60, in guide_add_referee
    'layout_data': get_layout_data(request)
  File "C:\Python34\lib\site-packages\django\shortcuts.py", line 67, in render
    template_name, context, request=request, using=using)
  File "C:\Python34\lib\site-packages\django\template\loader.py", line 96, in render_to_string
    template = get_template(template_name, using=using)
  File "C:\Python34\lib\site-packages\django\template\loader.py", line 32, in get_template
    return engine.get_template(template_name, dirs)
  File "C:\Python34\lib\site-packages\django\template\backends\django.py", line 40, in get_template
    return Template(self.engine.get_template(template_name, dirs), self)
  File "C:\Python34\lib\site-packages\django\template\engine.py", line 190, in get_template
    template, origin = self.find_template(template_name, dirs)
  File "C:\Python34\lib\site-packages\django\template\engine.py", line 157, in find_template
    name, template_dirs=dirs, skip=skip,
  File "C:\Python34\lib\site-packages\django\template\loaders\base.py", line 46, in get_template
    contents, origin, origin.template_name, self.engine,
  File "C:\Python34\lib\site-packages\django\template\base.py", line 189, in __init__
    self.nodelist = self.compile_nodelist()
  File "C:\Python34\lib\site-packages\django\template\base.py", line 230, in compile_nodelist
    return parser.parse()
  File "C:\Python34\lib\site-packages\django\template\base.py", line 514, in parse
    raise self.error(token, e)
  File "C:\Python34\lib\site-packages\django\template\base.py", line 512, in parse
    compiled_result = compile_func(self, token)
  File "C:\Python34\lib\site-packages\django\template\loader_tags.py", line 267, in do_extends
    nodelist = parser.parse()
  File "C:\Python34\lib\site-packages\django\template\base.py", line 514, in parse
    raise self.error(token, e)
  File "C:\Python34\lib\site-packages\django\template\base.py", line 512, in parse
    compiled_result = compile_func(self, token)
  File "C:\Python34\lib\site-packages\django\template\loader_tags.py", line 241, in do_block
    nodelist = parser.parse(('endblock',))
  File "C:\Python34\lib\site-packages\django\template\base.py", line 514, in parse
    raise self.error(token, e)
  File "C:\Python34\lib\site-packages\django\template\base.py", line 512, in parse
    compiled_result = compile_func(self, token)
  File "C:\Python34\lib\site-packages\django\template\defaulttags.py", line 1027, in do_if
    condition = TemplateIfParser(parser, bits).parse()
  File "C:\Python34\lib\site-packages\django\template\defaulttags.py", line 959, in __init__
    super(TemplateIfParser, self).__init__(*args, **kwargs)
  File "C:\Python34\lib\site-packages\django\template\smartif.py", line 168, in __init__
    mapped_tokens.append(self.translate_token(token))
  File "C:\Python34\lib\site-packages\django\template\smartif.py", line 179, in translate_token
    return self.create_var(token)
  File "C:\Python34\lib\site-packages\django\template\defaulttags.py", line 962, in create_var
    return TemplateLiteral(self.template_parser.compile_filter(value), value)
  File "C:\Python34\lib\site-packages\django\template\base.py", line 597, in compile_filter
    return FilterExpression(token, self)
  File "C:\Python34\lib\site-packages\django\template\base.py", line 697, in __init__
    "from '%s'" % (token[upto:], token))
django.template.exceptions.TemplateSyntaxError: Could not parse the remainder: '===' from '==='
2017-04-19 02:37:05 - INFO - views:logout:412 - User pavan successfully logged out
2017-04-19 04:34:57 - INFO - views:login:390 - User pavan successfully authenticated
2017-04-19 04:35:34 - ERROR - base:handle_uncaught_exception:284 - Internal Server Error: /guide/add/referee/
Traceback (most recent call last):
  File "C:\Python34\lib\site-packages\django\core\handlers\base.py", line 149, in get_response
    response = self.process_exception_by_middleware(e, request)
  File "C:\Python34\lib\site-packages\django\core\handlers\base.py", line 147, in get_response
    response = wrapped_callback(request, *callback_args, **callback_kwargs)
  File "D:\Github Projects\PhDPortal\app\guide_views.py", line 43, in guide_add_referee
    referee_form.save(new_user, user)
TypeError: save() takes from 1 to 2 positional arguments but 3 were given
2017-04-19 05:03:17 - INFO - views:logout:412 - User pavan successfully logged out
2017-04-19 05:03:22 - INFO - views:login:390 - User admin successfully authenticated
2017-04-19 05:13:38 - INFO - views:logout:412 - User admin successfully logged out
2017-04-19 05:13:46 - INFO - views:login:390 - User shawn successfully authenticated
2017-04-19 06:23:52 - INFO - views:logout:412 - User shawn successfully logged out
2017-04-19 06:23:58 - INFO - views:login:390 - User pavan successfully authenticated
2017-04-19 07:34:41 - INFO - views:logout:412 - User pavan successfully logged out
2017-04-19 07:34:47 - INFO - views:login:390 - User admin successfully authenticated
2017-04-19 07:40:09 - ERROR - base:handle_uncaught_exception:284 - Internal Server Error: /admin/approve/referee/
Traceback (most recent call last):
  File "C:\Python34\lib\site-packages\django\core\handlers\base.py", line 149, in get_response
    response = self.process_exception_by_middleware(e, request)
  File "C:\Python34\lib\site-packages\django\core\handlers\base.py", line 147, in get_response
    response = wrapped_callback(request, *callback_args, **callback_kwargs)
  File "C:\Python34\lib\site-packages\django\contrib\auth\decorators.py", line 23, in _wrapped_view
    return view_func(request, *args, **kwargs)
  File "D:\Github Projects\PhDPortal\app\admin_views.py", line 112, in admin_approve_referee
    guide = Faculty.objects.get(user = added_by)
NameError: name 'added_by' is not defined
2017-04-19 07:41:54 - ERROR - base:handle_uncaught_exception:284 - Internal Server Error: /admin/approve/referee/
Traceback (most recent call last):
  File "C:\Python34\lib\site-packages\django\core\handlers\base.py", line 149, in get_response
    response = self.process_exception_by_middleware(e, request)
  File "C:\Python34\lib\site-packages\django\core\handlers\base.py", line 147, in get_response
    response = wrapped_callback(request, *callback_args, **callback_kwargs)
  File "C:\Python34\lib\site-packages\django\contrib\auth\decorators.py", line 23, in _wrapped_view
    return view_func(request, *args, **kwargs)
  File "D:\Github Projects\PhDPortal\app\admin_views.py", line 112, in admin_approve_referee
    guide = Faculty.objects.get(user = ref.user)
  File "C:\Python34\lib\site-packages\django\db\models\manager.py", line 122, in manager_method
    return getattr(self.get_queryset(), name)(*args, **kwargs)
  File "C:\Python34\lib\site-packages\django\db\models\query.py", line 387, in get
    self.model._meta.object_name
app.models.DoesNotExist: Faculty matching query does not exist.
2017-04-19 07:42:26 - ERROR - base:handle_uncaught_exception:284 - Internal Server Error: /admin/approve/referee/
Traceback (most recent call last):
  File "C:\Python34\lib\site-packages\django\core\handlers\base.py", line 149, in get_response
    response = self.process_exception_by_middleware(e, request)
  File "C:\Python34\lib\site-packages\django\core\handlers\base.py", line 147, in get_response
    response = wrapped_callback(request, *callback_args, **callback_kwargs)
  File "C:\Python34\lib\site-packages\django\contrib\auth\decorators.py", line 23, in _wrapped_view
    return view_func(request, *args, **kwargs)
  File "D:\Github Projects\PhDPortal\app\admin_views.py", line 112, in admin_approve_referee
    guide = Faculty.objects.get(user = ref.user)
  File "C:\Python34\lib\site-packages\django\db\models\manager.py", line 122, in manager_method
    return getattr(self.get_queryset(), name)(*args, **kwargs)
  File "C:\Python34\lib\site-packages\django\db\models\query.py", line 387, in get
    self.model._meta.object_name
app.models.DoesNotExist: Faculty matching query does not exist.
2017-04-19 07:44:24 - ERROR - base:handle_uncaught_exception:284 - Internal Server Error: /admin/approve/referee/
Traceback (most recent call last):
  File "C:\Python34\lib\site-packages\django\core\handlers\base.py", line 149, in get_response
    response = self.process_exception_by_middleware(e, request)
  File "C:\Python34\lib\site-packages\django\core\handlers\base.py", line 147, in get_response
    response = wrapped_callback(request, *callback_args, **callback_kwargs)
  File "C:\Python34\lib\site-packages\django\contrib\auth\decorators.py", line 23, in _wrapped_view
    return view_func(request, *args, **kwargs)
  File "D:\Github Projects\PhDPortal\app\admin_views.py", line 112, in admin_approve_referee
    guide = Faculty.objects.get(user = referee)
  File "C:\Python34\lib\site-packages\django\db\models\manager.py", line 122, in manager_method
    return getattr(self.get_queryset(), name)(*args, **kwargs)
  File "C:\Python34\lib\site-packages\django\db\models\query.py", line 387, in get
    self.model._meta.object_name
app.models.DoesNotExist: Faculty matching query does not exist.
2017-04-19 07:48:38 - ERROR - base:handle_uncaught_exception:284 - Internal Server Error: /admin/approve/referee/
Traceback (most recent call last):
  File "C:\Python34\lib\site-packages\django\core\handlers\base.py", line 149, in get_response
    response = self.process_exception_by_middleware(e, request)
  File "C:\Python34\lib\site-packages\django\core\handlers\base.py", line 147, in get_response
    response = wrapped_callback(request, *callback_args, **callback_kwargs)
  File "C:\Python34\lib\site-packages\django\contrib\auth\decorators.py", line 23, in _wrapped_view
    return view_func(request, *args, **kwargs)
  File "D:\Github Projects\PhDPortal\app\admin_views.py", line 112, in admin_approve_referee
    guide_user = User.objects.get(id = ref.user)
  File "C:\Python34\lib\site-packages\django\db\models\manager.py", line 122, in manager_method
    return getattr(self.get_queryset(), name)(*args, **kwargs)
  File "C:\Python34\lib\site-packages\django\db\models\query.py", line 378, in get
    clone = self.filter(*args, **kwargs)
  File "C:\Python34\lib\site-packages\django\db\models\query.py", line 790, in filter
    return self._filter_or_exclude(False, *args, **kwargs)
  File "C:\Python34\lib\site-packages\django\db\models\query.py", line 808, in _filter_or_exclude
    clone.query.add_q(Q(*args, **kwargs))
  File "C:\Python34\lib\site-packages\django\db\models\sql\query.py", line 1243, in add_q
    clause, _ = self._add_q(q_object, self.used_aliases)
  File "C:\Python34\lib\site-packages\django\db\models\sql\query.py", line 1269, in _add_q
    allow_joins=allow_joins, split_subq=split_subq,
  File "C:\Python34\lib\site-packages\django\db\models\sql\query.py", line 1203, in build_filter
    condition = self.build_lookup(lookups, col, value)
  File "C:\Python34\lib\site-packages\django\db\models\sql\query.py", line 1099, in build_lookup
    return final_lookup(lhs, rhs)
  File "C:\Python34\lib\site-packages\django\db\models\lookups.py", line 19, in __init__
    self.rhs = self.get_prep_lookup()
  File "C:\Python34\lib\site-packages\django\db\models\lookups.py", line 57, in get_prep_lookup
    return self.lhs.output_field.get_prep_lookup(self.lookup_name, self.rhs)
  File "C:\Python34\lib\site-packages\django\db\models\fields\__init__.py", line 744, in get_prep_lookup
    return self.get_prep_value(value)
  File "C:\Python34\lib\site-packages\django\db\models\fields\__init__.py", line 976, in get_prep_value
    return int(value)
TypeError: int() argument must be a string or a number, not 'User'
2017-04-19 07:49:08 - ERROR - base:handle_uncaught_exception:284 - Internal Server Error: /admin/approve/referee/
Traceback (most recent call last):
  File "C:\Python34\lib\site-packages\django\core\handlers\base.py", line 149, in get_response
    response = self.process_exception_by_middleware(e, request)
  File "C:\Python34\lib\site-packages\django\core\handlers\base.py", line 147, in get_response
    response = wrapped_callback(request, *callback_args, **callback_kwargs)
  File "C:\Python34\lib\site-packages\django\contrib\auth\decorators.py", line 23, in _wrapped_view
    return view_func(request, *args, **kwargs)
  File "D:\Github Projects\PhDPortal\app\admin_views.py", line 113, in admin_approve_referee
    guide = Faculty.objects.get(user = guide_user)
  File "C:\Python34\lib\site-packages\django\db\models\manager.py", line 122, in manager_method
    return getattr(self.get_queryset(), name)(*args, **kwargs)
  File "C:\Python34\lib\site-packages\django\db\models\query.py", line 387, in get
    self.model._meta.object_name
app.models.DoesNotExist: Faculty matching query does not exist.
2017-04-19 07:53:25 - ERROR - base:handle_uncaught_exception:284 - Internal Server Error: /admin/approve/referee/
Traceback (most recent call last):
  File "C:\Python34\lib\site-packages\django\core\handlers\base.py", line 149, in get_response
    response = self.process_exception_by_middleware(e, request)
  File "C:\Python34\lib\site-packages\django\core\handlers\base.py", line 147, in get_response
    response = wrapped_callback(request, *callback_args, **callback_kwargs)
  File "C:\Python34\lib\site-packages\django\contrib\auth\decorators.py", line 23, in _wrapped_view
    return view_func(request, *args, **kwargs)
  File "D:\Github Projects\PhDPortal\app\admin_views.py", line 115, in admin_approve_referee
    dict['added_by'] = guide.first_name + ' ' + guide.last_name
NameError: name 'guide' is not defined
2017-04-19 10:19:50 - INFO - views:login:390 - User pavan successfully authenticated
2017-04-19 10:24:01 - INFO - views:logout:412 - User pavan successfully logged out
2017-04-19 10:24:12 - INFO - views:login:390 - User admin successfully authenticated
2017-04-19 10:42:33 - ERROR - base:handle_uncaught_exception:284 - Internal Server Error: /admin/add/referee/
Traceback (most recent call last):
  File "C:\Python34\lib\site-packages\django\core\handlers\base.py", line 149, in get_response
    response = self.process_exception_by_middleware(e, request)
  File "C:\Python34\lib\site-packages\django\core\handlers\base.py", line 147, in get_response
    response = wrapped_callback(request, *callback_args, **callback_kwargs)
  File "C:\Python34\lib\site-packages\django\contrib\auth\decorators.py", line 23, in _wrapped_view
    return view_func(request, *args, **kwargs)
  File "D:\Github Projects\PhDPortal\app\admin_views.py", line 65, in admin_add_referee
    message = "You are added to the PhDPortal of IIIT-Allahabad.Please kindly check the Portal and update your Password.<br>Username is "+ user_form.username + "<br>Password is" + passwd + "<br>"
TypeError: Can't convert 'CharField' object to str implicitly
2017-04-19 10:46:16 - INFO - views:logout:412 - User admin successfully logged out
2017-04-19 10:46:22 - INFO - views:login:390 - User heath successfully authenticated
2017-04-19 10:47:36 - INFO - views:logout:412 - User heath successfully logged out
2017-04-19 10:47:41 - INFO - views:login:390 - User pavan successfully authenticated
2017-04-19 10:49:31 - ERROR - base:handle_uncaught_exception:284 - Internal Server Error: /guide/add/referee/
Traceback (most recent call last):
  File "C:\Python34\lib\site-packages\django\core\handlers\base.py", line 149, in get_response
    response = self.process_exception_by_middleware(e, request)
  File "C:\Python34\lib\site-packages\django\core\handlers\base.py", line 147, in get_response
    response = wrapped_callback(request, *callback_args, **callback_kwargs)
  File "D:\Github Projects\PhDPortal\app\guide_views.py", line 54, in guide_add_referee
    send_notification(user, admin.user, message, '')
UnboundLocalError: local variable 'message' referenced before assignment
2017-04-19 10:51:24 - INFO - views:logout:412 - User pavan successfully logged out
2017-04-19 10:51:29 - INFO - views:login:390 - User admin successfully authenticated
2017-04-19 10:52:16 - ERROR - base:handle_uncaught_exception:284 - Internal Server Error: /admin/add/referee/
Traceback (most recent call last):
  File "C:\Python34\lib\site-packages\django\core\handlers\base.py", line 149, in get_response
    response = self.process_exception_by_middleware(e, request)
  File "C:\Python34\lib\site-packages\django\core\handlers\base.py", line 147, in get_response
    response = wrapped_callback(request, *callback_args, **callback_kwargs)
  File "C:\Python34\lib\site-packages\django\contrib\auth\decorators.py", line 23, in _wrapped_view
    return view_func(request, *args, **kwargs)
  File "D:\Github Projects\PhDPortal\app\admin_views.py", line 65, in admin_add_referee
    message = "You are added to the PhDPortal of IIIT-Allahabad.Please kindly check the Portal and update your Password.<br>Username is "+ str(user_form.username) + "<br>Password is" + str(passwd) + "<br>"
  File "C:\Python34\lib\site-packages\django\db\models\fields\__init__.py", line 188, in __str__
    model = self.model
AttributeError: 'CharField' object has no attribute 'model'
2017-04-19 10:53:58 - ERROR - base:handle_uncaught_exception:284 - Internal Server Error: /admin/add/referee/
Traceback (most recent call last):
  File "C:\Python34\lib\site-packages\django\core\handlers\base.py", line 149, in get_response
    response = self.process_exception_by_middleware(e, request)
  File "C:\Python34\lib\site-packages\django\core\handlers\base.py", line 147, in get_response
    response = wrapped_callback(request, *callback_args, **callback_kwargs)
  File "C:\Python34\lib\site-packages\django\contrib\auth\decorators.py", line 23, in _wrapped_view
    return view_func(request, *args, **kwargs)
  File "D:\Github Projects\PhDPortal\app\admin_views.py", line 65, in admin_add_referee
    message = "You are added to the PhDPortal of IIIT-Allahabad.Please kindly check the Portal and update your Password.<br>Username is "+ user_form.username.value_to_string + "<br>Password is" + passwd + "<br>"
TypeError: Can't convert 'method' object to str implicitly
2017-04-19 10:55:05 - ERROR - base:handle_uncaught_exception:284 - Internal Server Error: /admin/add/referee/
Traceback (most recent call last):
  File "C:\Python34\lib\site-packages\django\core\handlers\base.py", line 149, in get_response
    response = self.process_exception_by_middleware(e, request)
  File "C:\Python34\lib\site-packages\django\core\handlers\base.py", line 147, in get_response
    response = wrapped_callback(request, *callback_args, **callback_kwargs)
  File "C:\Python34\lib\site-packages\django\contrib\auth\decorators.py", line 23, in _wrapped_view
    return view_func(request, *args, **kwargs)
  File "D:\Github Projects\PhDPortal\app\admin_views.py", line 65, in admin_add_referee
    message = "You are added to the PhDPortal of IIIT-Allahabad.Please kindly check the Portal and update your Password.<br>Username is "+ user_form.username.value_to_string() + "<br>Password is" + passwd + "<br>"
TypeError: value_to_string() missing 1 required positional argument: 'obj'
2017-04-19 10:59:04 - INFO - views:logout:412 - User admin successfully logged out
2017-04-19 10:59:12 - INFO - views:login:390 - User billy successfully authenticated
2017-04-19 11:04:17 - INFO - views:logout:412 - User billy successfully logged out
2017-04-19 11:04:22 - INFO - views:login:390 - User admin successfully authenticated
2017-04-19 11:05:23 - INFO - views:logout:412 - User admin successfully logged out
2017-04-19 11:05:28 - INFO - views:login:390 - User simon successfully authenticated
2017-04-19 11:11:33 - INFO - views:logout:412 - User simon successfully logged out
2017-04-19 11:19:27 - ERROR - base:handle_uncaught_exception:284 - Internal Server Error: /forgotpassword
Traceback (most recent call last):
  File "C:\Python34\lib\site-packages\django\core\handlers\base.py", line 149, in get_response
    response = self.process_exception_by_middleware(e, request)
  File "C:\Python34\lib\site-packages\django\core\handlers\base.py", line 147, in get_response
    response = wrapped_callback(request, *callback_args, **callback_kwargs)
TypeError: forgotpassword() takes 0 positional arguments but 1 was given
2017-04-19 11:20:05 - ERROR - base:handle_uncaught_exception:284 - Internal Server Error: /forgotpassword
Traceback (most recent call last):
  File "C:\Python34\lib\site-packages\django\core\handlers\base.py", line 149, in get_response
    response = self.process_exception_by_middleware(e, request)
  File "C:\Python34\lib\site-packages\django\core\handlers\base.py", line 147, in get_response
    response = wrapped_callback(request, *callback_args, **callback_kwargs)
TypeError: forgotpassword() takes 0 positional arguments but 1 was given
2017-04-19 11:20:51 - ERROR - base:handle_uncaught_exception:284 - Internal Server Error: /forgotpassword
Traceback (most recent call last):
  File "C:\Python34\lib\site-packages\django\core\handlers\base.py", line 149, in get_response
    response = self.process_exception_by_middleware(e, request)
  File "C:\Python34\lib\site-packages\django\core\handlers\base.py", line 147, in get_response
    response = wrapped_callback(request, *callback_args, **callback_kwargs)
TypeError: forgotpassword() takes 0 positional arguments but 1 was given
2017-04-19 11:21:57 - ERROR - base:handle_uncaught_exception:284 - Internal Server Error: /forgotpassword
Traceback (most recent call last):
  File "C:\Python34\lib\site-packages\django\core\handlers\base.py", line 149, in get_response
    response = self.process_exception_by_middleware(e, request)
  File "C:\Python34\lib\site-packages\django\core\handlers\base.py", line 147, in get_response
    response = wrapped_callback(request, *callback_args, **callback_kwargs)
TypeError: forgotpassword() takes 0 positional arguments but 1 was given
2017-04-19 11:22:52 - ERROR - base:handle_uncaught_exception:284 - Internal Server Error: /forgotpassword
Traceback (most recent call last):
  File "C:\Python34\lib\site-packages\django\core\handlers\base.py", line 149, in get_response
    response = self.process_exception_by_middleware(e, request)
  File "C:\Python34\lib\site-packages\django\core\handlers\base.py", line 147, in get_response
    response = wrapped_callback(request, *callback_args, **callback_kwargs)
TypeError: forgotpassword() takes 0 positional arguments but 1 was given
2017-04-19 11:24:00 - ERROR - base:handle_uncaught_exception:284 - Internal Server Error: /forgotpassword
Traceback (most recent call last):
  File "C:\Python34\lib\site-packages\django\core\handlers\base.py", line 149, in get_response
    response = self.process_exception_by_middleware(e, request)
  File "C:\Python34\lib\site-packages\django\core\handlers\base.py", line 147, in get_response
    response = wrapped_callback(request, *callback_args, **callback_kwargs)
  File "D:\Github Projects\PhDPortal\app\views.py", line 49, in forgotpassword
    if request.method == 'GET':
NameError: name 'request' is not defined
2017-04-19 11:24:17 - ERROR - base:handle_uncaught_exception:284 - Internal Server Error: /forgotpassword
Traceback (most recent call last):
  File "C:\Python34\lib\site-packages\django\core\handlers\base.py", line 149, in get_response
    response = self.process_exception_by_middleware(e, request)
  File "C:\Python34\lib\site-packages\django\core\handlers\base.py", line 147, in get_response
    response = wrapped_callback(request, *callback_args, **callback_kwargs)
  File "D:\Github Projects\PhDPortal\app\views.py", line 50, in forgotpassword
    return render('app/other/forgot_password.html', {'title':'Forgot Password?',})
  File "C:\Python34\lib\site-packages\django\shortcuts.py", line 67, in render
    template_name, context, request=request, using=using)
  File "C:\Python34\lib\site-packages\django\template\loader.py", line 96, in render_to_string
    template = get_template(template_name, using=using)
  File "C:\Python34\lib\site-packages\django\template\loader.py", line 43, in get_template
    raise TemplateDoesNotExist(template_name, chain=chain)
django.template.exceptions.TemplateDoesNotExist: {'title': 'Forgot Password?'}
2017-04-19 11:24:18 - ERROR - base:handle_uncaught_exception:284 - Internal Server Error: /forgotpassword
Traceback (most recent call last):
  File "C:\Python34\lib\site-packages\django\core\handlers\base.py", line 149, in get_response
    response = self.process_exception_by_middleware(e, request)
  File "C:\Python34\lib\site-packages\django\core\handlers\base.py", line 147, in get_response
    response = wrapped_callback(request, *callback_args, **callback_kwargs)
  File "D:\Github Projects\PhDPortal\app\views.py", line 50, in forgotpassword
    return render('app/other/forgot_password.html', {'title':'Forgot Password?',})
  File "C:\Python34\lib\site-packages\django\shortcuts.py", line 67, in render
    template_name, context, request=request, using=using)
  File "C:\Python34\lib\site-packages\django\template\loader.py", line 96, in render_to_string
    template = get_template(template_name, using=using)
  File "C:\Python34\lib\site-packages\django\template\loader.py", line 43, in get_template
    raise TemplateDoesNotExist(template_name, chain=chain)
django.template.exceptions.TemplateDoesNotExist: {'title': 'Forgot Password?'}
2017-04-19 11:32:43 - INFO - views:login:402 - User admin successfully authenticated
2017-04-19 12:20:21 - ERROR - base:handle_uncaught_exception:284 - Internal Server Error: /admin/approve/referee/
Traceback (most recent call last):
  File "C:\Python34\lib\site-packages\django\core\handlers\base.py", line 149, in get_response
    response = self.process_exception_by_middleware(e, request)
  File "C:\Python34\lib\site-packages\django\core\handlers\base.py", line 147, in get_response
    response = wrapped_callback(request, *callback_args, **callback_kwargs)
  File "C:\Python34\lib\site-packages\django\contrib\auth\decorators.py", line 23, in _wrapped_view
    return view_func(request, *args, **kwargs)
  File "D:\Github Projects\PhDPortal\app\admin_views.py", line 156, in admin_approve_referee
    'suggested_referees' : suggested_referees,
UnboundLocalError: local variable 'suggested_referees' referenced before assignment
2017-04-19 12:21:29 - INFO - views:login:402 - User admin successfully authenticated
2017-04-19 12:21:32 - ERROR - base:handle_uncaught_exception:284 - Internal Server Error: /admin/approve/referee/
Traceback (most recent call last):
  File "C:\Python34\lib\site-packages\django\core\handlers\base.py", line 149, in get_response
    response = self.process_exception_by_middleware(e, request)
  File "C:\Python34\lib\site-packages\django\core\handlers\base.py", line 147, in get_response
    response = wrapped_callback(request, *callback_args, **callback_kwargs)
  File "C:\Python34\lib\site-packages\django\contrib\auth\decorators.py", line 23, in _wrapped_view
    return view_func(request, *args, **kwargs)
  File "D:\Github Projects\PhDPortal\app\admin_views.py", line 147, in admin_approve_referee
    suggested_referees.append(dict)
UnboundLocalError: local variable 'suggested_referees' referenced before assignment
2017-04-19 12:22:10 - ERROR - base:handle_uncaught_exception:284 - Internal Server Error: /admin/approve/referee/
Traceback (most recent call last):
  File "C:\Python34\lib\site-packages\django\core\handlers\base.py", line 149, in get_response
    response = self.process_exception_by_middleware(e, request)
  File "C:\Python34\lib\site-packages\django\core\handlers\base.py", line 147, in get_response
    response = wrapped_callback(request, *callback_args, **callback_kwargs)
  File "C:\Python34\lib\site-packages\django\contrib\auth\decorators.py", line 23, in _wrapped_view
    return view_func(request, *args, **kwargs)
  File "D:\Github Projects\PhDPortal\app\admin_views.py", line 147, in admin_approve_referee
    suggested_referees.append(dict)
UnboundLocalError: local variable 'suggested_referees' referenced before assignment
2017-04-19 12:47:45 - ERROR - base:handle_uncaught_exception:284 - Internal Server Error: /admin/approve/referee/
Traceback (most recent call last):
  File "C:\Python34\lib\site-packages\django\core\handlers\base.py", line 149, in get_response
    response = self.process_exception_by_middleware(e, request)
  File "C:\Python34\lib\site-packages\django\core\handlers\base.py", line 147, in get_response
    response = wrapped_callback(request, *callback_args, **callback_kwargs)
  File "C:\Python34\lib\site-packages\django\contrib\auth\decorators.py", line 23, in _wrapped_view
    return view_func(request, *args, **kwargs)
  File "D:\Github Projects\PhDPortal\app\admin_views.py", line 139, in admin_approve_referee
    guide_user = User.objects.get(id = ref.added_by.id)
AttributeError: 'QuerySet' object has no attribute 'added_by'
2017-04-19 12:47:47 - ERROR - base:handle_uncaught_exception:284 - Internal Server Error: /admin/approve/referee/
Traceback (most recent call last):
  File "C:\Python34\lib\site-packages\django\core\handlers\base.py", line 149, in get_response
    response = self.process_exception_by_middleware(e, request)
  File "C:\Python34\lib\site-packages\django\core\handlers\base.py", line 147, in get_response
    response = wrapped_callback(request, *callback_args, **callback_kwargs)
  File "C:\Python34\lib\site-packages\django\contrib\auth\decorators.py", line 23, in _wrapped_view
    return view_func(request, *args, **kwargs)
  File "D:\Github Projects\PhDPortal\app\admin_views.py", line 139, in admin_approve_referee
    guide_user = User.objects.get(id = ref.added_by.id)
AttributeError: 'QuerySet' object has no attribute 'added_by'
2017-04-19 12:48:08 - ERROR - base:handle_uncaught_exception:284 - Internal Server Error: /admin/approve/referee/
Traceback (most recent call last):
  File "C:\Python34\lib\site-packages\django\core\handlers\base.py", line 149, in get_response
    response = self.process_exception_by_middleware(e, request)
  File "C:\Python34\lib\site-packages\django\core\handlers\base.py", line 147, in get_response
    response = wrapped_callback(request, *callback_args, **callback_kwargs)
  File "C:\Python34\lib\site-packages\django\contrib\auth\decorators.py", line 23, in _wrapped_view
    return view_func(request, *args, **kwargs)
  File "D:\Github Projects\PhDPortal\app\admin_views.py", line 156, in admin_approve_referee
    'layout_data': get_layout_data(request)
  File "C:\Python34\lib\site-packages\django\shortcuts.py", line 67, in render
    template_name, context, request=request, using=using)
  File "C:\Python34\lib\site-packages\django\template\loader.py", line 97, in render_to_string
    return template.render(context, request)
  File "C:\Python34\lib\site-packages\django\template\backends\django.py", line 95, in render
    return self.template.render(context)
  File "C:\Python34\lib\site-packages\django\template\base.py", line 206, in render
    return self._render(context)
  File "C:\Python34\lib\site-packages\django\template\base.py", line 197, in _render
    return self.nodelist.render(context)
  File "C:\Python34\lib\site-packages\django\template\base.py", line 988, in render
    bit = node.render_annotated(context)
  File "C:\Python34\lib\site-packages\django\template\base.py", line 955, in render_annotated
    return self.render(context)
  File "C:\Python34\lib\site-packages\django\template\loader_tags.py", line 173, in render
    return compiled_parent._render(context)
  File "C:\Python34\lib\site-packages\django\template\base.py", line 197, in _render
    return self.nodelist.render(context)
  File "C:\Python34\lib\site-packages\django\template\base.py", line 988, in render
    bit = node.render_annotated(context)
  File "C:\Python34\lib\site-packages\django\template\base.py", line 955, in render_annotated
    return self.render(context)
  File "C:\Python34\lib\site-packages\django\template\loader_tags.py", line 69, in render
    result = block.nodelist.render(context)
  File "C:\Python34\lib\site-packages\django\template\base.py", line 988, in render
    bit = node.render_annotated(context)
  File "C:\Python34\lib\site-packages\django\template\base.py", line 955, in render_annotated
    return self.render(context)
  File "C:\Python34\lib\site-packages\django\template\defaulttags.py", line 220, in render
    nodelist.append(node.render_annotated(context))
  File "C:\Python34\lib\site-packages\django\template\base.py", line 955, in render_annotated
    return self.render(context)
  File "C:\Python34\lib\site-packages\django\template\defaulttags.py", line 220, in render
    nodelist.append(node.render_annotated(context))
  File "C:\Python34\lib\site-packages\django\template\base.py", line 955, in render_annotated
    return self.render(context)
  File "C:\Python34\lib\site-packages\django\template\base.py", line 1045, in render
    return render_value_in_context(output, context)
  File "C:\Python34\lib\site-packages\django\template\base.py", line 1022, in render_value_in_context
    value = force_text(value)
  File "C:\Python34\lib\site-packages\django\utils\encoding.py", line 76, in force_text
    s = six.text_type(s)
  File "C:\Python34\lib\site-packages\django\utils\html.py", line 390, in <lambda>
    klass.__str__ = lambda self: mark_safe(klass_str(self))
  File "C:\Python34\lib\site-packages\django\forms\boundfield.py", line 43, in __str__
    return self.as_widget()
  File "C:\Python34\lib\site-packages\django\forms\boundfield.py", line 101, in as_widget
    return force_text(widget.render(name, self.value(), attrs=attrs))
  File "C:\Python34\lib\site-packages\django\forms\boundfield.py", line 146, in value
    self.data, self.form.initial.get(self.name, self.field.initial)
  File "C:\Python34\lib\site-packages\django\forms\boundfield.py", line 124, in data
    return self.field.widget.value_from_datadict(self.form.data, self.form.files, self.html_name)
  File "C:\Python34\lib\site-packages\django\forms\widgets.py", line 231, in value_from_datadict
    return data.get(name)
AttributeError: 'User' object has no attribute 'get'
2017-04-19 12:54:52 - ERROR - base:handle_uncaught_exception:284 - Internal Server Error: /admin/approve/referee/
Traceback (most recent call last):
  File "C:\Python34\lib\site-packages\django\core\handlers\base.py", line 149, in get_response
    response = self.process_exception_by_middleware(e, request)
  File "C:\Python34\lib\site-packages\django\core\handlers\base.py", line 147, in get_response
    response = wrapped_callback(request, *callback_args, **callback_kwargs)
  File "C:\Python34\lib\site-packages\django\contrib\auth\decorators.py", line 23, in _wrapped_view
    return view_func(request, *args, **kwargs)
  File "D:\Github Projects\PhDPortal\app\admin_views.py", line 142, in admin_approve_referee
    user_form = UserForm()
TypeError: __init__() missing 1 required positional argument: 'user'
2017-04-19 13:09:03 - ERROR - base:handle_uncaught_exception:284 - Internal Server Error: /admin/add/referee/
Traceback (most recent call last):
  File "C:\Python34\lib\site-packages\django\core\handlers\base.py", line 149, in get_response
    response = self.process_exception_by_middleware(e, request)
  File "C:\Python34\lib\site-packages\django\core\handlers\base.py", line 147, in get_response
    response = wrapped_callback(request, *callback_args, **callback_kwargs)
  File "C:\Python34\lib\site-packages\django\contrib\auth\decorators.py", line 23, in _wrapped_view
    return view_func(request, *args, **kwargs)
  File "D:\Github Projects\PhDPortal\app\admin_views.py", line 82, in admin_add_referee
    user_form = UserForm()
TypeError: __init__() missing 1 required positional argument: 'thisuser'
2017-04-19 13:11:48 - ERROR - base:handle_uncaught_exception:284 - Internal Server Error: /admin/approve/referee/
Traceback (most recent call last):
  File "C:\Python34\lib\site-packages\django\core\handlers\base.py", line 149, in get_response
    response = self.process_exception_by_middleware(e, request)
  File "C:\Python34\lib\site-packages\django\core\handlers\base.py", line 147, in get_response
    response = wrapped_callback(request, *callback_args, **callback_kwargs)
  File "C:\Python34\lib\site-packages\django\contrib\auth\decorators.py", line 23, in _wrapped_view
    return view_func(request, *args, **kwargs)
  File "D:\Github Projects\PhDPortal\app\admin_views.py", line 156, in admin_approve_referee
    'layout_data': get_layout_data(request)
  File "C:\Python34\lib\site-packages\django\shortcuts.py", line 67, in render
    template_name, context, request=request, using=using)
  File "C:\Python34\lib\site-packages\django\template\loader.py", line 97, in render_to_string
    return template.render(context, request)
  File "C:\Python34\lib\site-packages\django\template\backends\django.py", line 95, in render
    return self.template.render(context)
  File "C:\Python34\lib\site-packages\django\template\base.py", line 206, in render
    return self._render(context)
  File "C:\Python34\lib\site-packages\django\template\base.py", line 197, in _render
    return self.nodelist.render(context)
  File "C:\Python34\lib\site-packages\django\template\base.py", line 988, in render
    bit = node.render_annotated(context)
  File "C:\Python34\lib\site-packages\django\template\base.py", line 955, in render_annotated
    return self.render(context)
  File "C:\Python34\lib\site-packages\django\template\loader_tags.py", line 173, in render
    return compiled_parent._render(context)
  File "C:\Python34\lib\site-packages\django\template\base.py", line 197, in _render
    return self.nodelist.render(context)
  File "C:\Python34\lib\site-packages\django\template\base.py", line 988, in render
    bit = node.render_annotated(context)
  File "C:\Python34\lib\site-packages\django\template\base.py", line 955, in render_annotated
    return self.render(context)
  File "C:\Python34\lib\site-packages\django\template\loader_tags.py", line 69, in render
    result = block.nodelist.render(context)
  File "C:\Python34\lib\site-packages\django\template\base.py", line 988, in render
    bit = node.render_annotated(context)
  File "C:\Python34\lib\site-packages\django\template\base.py", line 955, in render_annotated
    return self.render(context)
  File "C:\Python34\lib\site-packages\django\template\defaulttags.py", line 220, in render
    nodelist.append(node.render_annotated(context))
  File "C:\Python34\lib\site-packages\django\template\base.py", line 955, in render_annotated
    return self.render(context)
  File "C:\Python34\lib\site-packages\django\template\defaulttags.py", line 167, in render
    values = list(values)
  File "C:\Python34\lib\site-packages\django\forms\forms.py", line 136, in __iter__
    yield self[name]
  File "C:\Python34\lib\site-packages\django\forms\forms.py", line 146, in __getitem__
    self._bound_fields_cache[name] = field.get_bound_field(self, name)
AttributeError: 'str' object has no attribute 'get_bound_field'
2017-04-19 13:16:09 - ERROR - base:handle_uncaught_exception:284 - Internal Server Error: /admin/add/referee/
Traceback (most recent call last):
  File "C:\Python34\lib\site-packages\django\core\handlers\base.py", line 149, in get_response
    response = self.process_exception_by_middleware(e, request)
  File "C:\Python34\lib\site-packages\django\core\handlers\base.py", line 147, in get_response
    response = wrapped_callback(request, *callback_args, **callback_kwargs)
  File "C:\Python34\lib\site-packages\django\contrib\auth\decorators.py", line 23, in _wrapped_view
    return view_func(request, *args, **kwargs)
  File "D:\Github Projects\PhDPortal\app\admin_views.py", line 82, in admin_add_referee
    user_form = UserForm(Null)
NameError: name 'Null' is not defined
2017-04-19 13:17:13 - ERROR - base:handle_uncaught_exception:284 - Internal Server Error: /admin/add/referee/
Traceback (most recent call last):
  File "C:\Python34\lib\site-packages\django\core\handlers\base.py", line 149, in get_response
    response = self.process_exception_by_middleware(e, request)
  File "C:\Python34\lib\site-packages\django\core\handlers\base.py", line 147, in get_response
    response = wrapped_callback(request, *callback_args, **callback_kwargs)
  File "C:\Python34\lib\site-packages\django\contrib\auth\decorators.py", line 23, in _wrapped_view
    return view_func(request, *args, **kwargs)
  File "D:\Github Projects\PhDPortal\app\admin_views.py", line 82, in admin_add_referee
    user_form = UserForm(Null)
NameError: name 'Null' is not defined
2017-04-19 13:17:48 - ERROR - base:handle_uncaught_exception:284 - Internal Server Error: /admin/add/referee/
Traceback (most recent call last):
  File "C:\Python34\lib\site-packages\django\core\handlers\base.py", line 149, in get_response
    response = self.process_exception_by_middleware(e, request)
  File "C:\Python34\lib\site-packages\django\core\handlers\base.py", line 147, in get_response
    response = wrapped_callback(request, *callback_args, **callback_kwargs)
  File "C:\Python34\lib\site-packages\django\contrib\auth\decorators.py", line 23, in _wrapped_view
    return view_func(request, *args, **kwargs)
  File "D:\Github Projects\PhDPortal\app\admin_views.py", line 82, in admin_add_referee
    user_form = UserForm(None)
  File "D:\Github Projects\PhDPortal\app\forms.py", line 82, in __init__
    if thisuser != Null:
NameError: name 'Null' is not defined
2017-04-19 13:20:39 - ERROR - base:handle_uncaught_exception:284 - Internal Server Error: /admin/approve/referee/
Traceback (most recent call last):
  File "C:\Python34\lib\site-packages\django\core\handlers\base.py", line 149, in get_response
    response = self.process_exception_by_middleware(e, request)
  File "C:\Python34\lib\site-packages\django\core\handlers\base.py", line 147, in get_response
    response = wrapped_callback(request, *callback_args, **callback_kwargs)
  File "C:\Python34\lib\site-packages\django\contrib\auth\decorators.py", line 23, in _wrapped_view
    return view_func(request, *args, **kwargs)
  File "D:\Github Projects\PhDPortal\app\admin_views.py", line 104, in admin_approve_referee
    user_form = UserForm(request.POST)
  File "D:\Github Projects\PhDPortal\app\forms.py", line 83, in __init__
    self.fields['first_name'].initial = thisuser.first_name
AttributeError: 'QueryDict' object has no attribute 'first_name'
2017-04-19 13:22:58 - ERROR - base:handle_uncaught_exception:284 - Internal Server Error: /admin/approve/referee/
Traceback (most recent call last):
  File "C:\Python34\lib\site-packages\django\core\handlers\base.py", line 149, in get_response
    response = self.process_exception_by_middleware(e, request)
  File "C:\Python34\lib\site-packages\django\core\handlers\base.py", line 147, in get_response
    response = wrapped_callback(request, *callback_args, **callback_kwargs)
  File "C:\Python34\lib\site-packages\django\contrib\auth\decorators.py", line 23, in _wrapped_view
    return view_func(request, *args, **kwargs)
  File "D:\Github Projects\PhDPortal\app\admin_views.py", line 104, in admin_approve_referee
    user_form = UserForm(request.POST,None)
  File "D:\Github Projects\PhDPortal\app\forms.py", line 83, in __init__
    self.fields['first_name'].initial = thisuser.first_name
AttributeError: 'QueryDict' object has no attribute 'first_name'
2017-04-19 13:23:08 - ERROR - base:handle_uncaught_exception:284 - Internal Server Error: /admin/approve/referee/
Traceback (most recent call last):
  File "C:\Python34\lib\site-packages\django\core\handlers\base.py", line 149, in get_response
    response = self.process_exception_by_middleware(e, request)
  File "C:\Python34\lib\site-packages\django\core\handlers\base.py", line 147, in get_response
    response = wrapped_callback(request, *callback_args, **callback_kwargs)
  File "C:\Python34\lib\site-packages\django\contrib\auth\decorators.py", line 23, in _wrapped_view
    return view_func(request, *args, **kwargs)
  File "D:\Github Projects\PhDPortal\app\admin_views.py", line 104, in admin_approve_referee
    user_form = UserForm(request.POST,None)
  File "D:\Github Projects\PhDPortal\app\forms.py", line 83, in __init__
    self.fields['first_name'].initial = thisuser.first_name
AttributeError: 'QueryDict' object has no attribute 'first_name'
2017-04-19 13:27:21 - ERROR - base:handle_uncaught_exception:284 - Internal Server Error: /admin/approve/referee/
Traceback (most recent call last):
  File "C:\Python34\lib\site-packages\django\core\handlers\base.py", line 149, in get_response
    response = self.process_exception_by_middleware(e, request)
  File "C:\Python34\lib\site-packages\django\core\handlers\base.py", line 147, in get_response
    response = wrapped_callback(request, *callback_args, **callback_kwargs)
  File "C:\Python34\lib\site-packages\django\contrib\auth\decorators.py", line 23, in _wrapped_view
    return view_func(request, *args, **kwargs)
  File "D:\Github Projects\PhDPortal\app\admin_views.py", line 104, in admin_approve_referee
    user_form = UserForm(request.POST)
  File "D:\Github Projects\PhDPortal\app\forms.py", line 83, in __init__
    self.fields['first_name'].initial = thisuser.first_name
AttributeError: 'QueryDict' object has no attribute 'first_name'
2017-04-19 13:43:59 - ERROR - base:handle_uncaught_exception:284 - Internal Server Error: /admin/approve/referee/
Traceback (most recent call last):
  File "C:\Python34\lib\site-packages\django\core\handlers\base.py", line 149, in get_response
    response = self.process_exception_by_middleware(e, request)
  File "C:\Python34\lib\site-packages\django\core\handlers\base.py", line 147, in get_response
    response = wrapped_callback(request, *callback_args, **callback_kwargs)
  File "C:\Python34\lib\site-packages\django\contrib\auth\decorators.py", line 23, in _wrapped_view
    return view_func(request, *args, **kwargs)
  File "D:\Github Projects\PhDPortal\app\admin_views.py", line 142, in admin_approve_referee
    user_form = UserForm(instance = referee)
TypeError: __init__() missing 1 required positional argument: 'thisuser'
2017-04-19 13:48:52 - ERROR - base:handle_uncaught_exception:284 - Internal Server Error: /admin/approve/referee/
Traceback (most recent call last):
  File "C:\Python34\lib\site-packages\django\core\handlers\base.py", line 149, in get_response
    response = self.process_exception_by_middleware(e, request)
  File "C:\Python34\lib\site-packages\django\core\handlers\base.py", line 147, in get_response
    response = wrapped_callback(request, *callback_args, **callback_kwargs)
  File "C:\Python34\lib\site-packages\django\contrib\auth\decorators.py", line 23, in _wrapped_view
    return view_func(request, *args, **kwargs)
  File "D:\Github Projects\PhDPortal\app\admin_views.py", line 142, in admin_approve_referee
    user_form = UserForm(instance = referee)
  File "D:\Github Projects\PhDPortal\app\forms.py", line 81, in __init__
    #self.initial['city'] = self.instance.name
AttributeError: 'User' object has no attribute 'name'
2017-04-19 13:49:58 - ERROR - base:handle_uncaught_exception:284 - Internal Server Error: /admin/approve/referee/
Traceback (most recent call last):
  File "C:\Python34\lib\site-packages\django\core\handlers\base.py", line 149, in get_response
    response = self.process_exception_by_middleware(e, request)
  File "C:\Python34\lib\site-packages\django\core\handlers\base.py", line 147, in get_response
    response = wrapped_callback(request, *callback_args, **callback_kwargs)
  File "C:\Python34\lib\site-packages\django\contrib\auth\decorators.py", line 23, in _wrapped_view
    return view_func(request, *args, **kwargs)
  File "D:\Github Projects\PhDPortal\app\admin_views.py", line 143, in admin_approve_referee
    referee_form = RefereeForm(instance =ref)
TypeError: __init__() missing 1 required positional argument: 'thisuser'
2017-04-19 13:50:59 - ERROR - base:handle_uncaught_exception:284 - Internal Server Error: /admin/approve/referee/
Traceback (most recent call last):
  File "C:\Python34\lib\site-packages\django\core\handlers\base.py", line 149, in get_response
    response = self.process_exception_by_middleware(e, request)
  File "C:\Python34\lib\site-packages\django\core\handlers\base.py", line 147, in get_response
    response = wrapped_callback(request, *callback_args, **callback_kwargs)
  File "C:\Python34\lib\site-packages\django\contrib\auth\decorators.py", line 23, in _wrapped_view
    return view_func(request, *args, **kwargs)
  File "D:\Github Projects\PhDPortal\app\admin_views.py", line 143, in admin_approve_referee
    referee_form = RefereeForm(instance =ref)
TypeError: __init__() missing 1 required positional argument: 'thisuser'
2017-04-19 13:53:51 - ERROR - base:handle_uncaught_exception:284 - Internal Server Error: /admin/approve/referee/
Traceback (most recent call last):
  File "C:\Python34\lib\site-packages\django\core\handlers\base.py", line 149, in get_response
    response = self.process_exception_by_middleware(e, request)
  File "C:\Python34\lib\site-packages\django\core\handlers\base.py", line 147, in get_response
    response = wrapped_callback(request, *callback_args, **callback_kwargs)
  File "C:\Python34\lib\site-packages\django\contrib\auth\decorators.py", line 23, in _wrapped_view
    return view_func(request, *args, **kwargs)
  File "D:\Github Projects\PhDPortal\app\admin_views.py", line 107, in admin_approve_referee
    if user_form.is_valid() and referee_form.is_valid():
  File "C:\Python34\lib\site-packages\django\forms\forms.py", line 161, in is_valid
    return self.is_bound and not self.errors
  File "C:\Python34\lib\site-packages\django\forms\forms.py", line 153, in errors
    self.full_clean()
  File "C:\Python34\lib\site-packages\django\forms\forms.py", line 364, in full_clean
    self._post_clean()
  File "C:\Python34\lib\site-packages\django\forms\models.py", line 377, in _post_clean
    exclude = self._get_validation_exclusions()
  File "C:\Python34\lib\site-packages\django\forms\models.py", line 309, in _get_validation_exclusions
    for f in self.instance._meta.fields:
AttributeError: 'NoneType' object has no attribute '_meta'
2017-04-19 13:54:55 - ERROR - base:handle_uncaught_exception:284 - Internal Server Error: /admin/approve/referee/
Traceback (most recent call last):
  File "C:\Python34\lib\site-packages\django\core\handlers\base.py", line 149, in get_response
    response = self.process_exception_by_middleware(e, request)
  File "C:\Python34\lib\site-packages\django\core\handlers\base.py", line 147, in get_response
    response = wrapped_callback(request, *callback_args, **callback_kwargs)
  File "C:\Python34\lib\site-packages\django\contrib\auth\decorators.py", line 23, in _wrapped_view
    return view_func(request, *args, **kwargs)
  File "D:\Github Projects\PhDPortal\app\admin_views.py", line 107, in admin_approve_referee
    if user_form.is_valid() and referee_form.is_valid():
  File "C:\Python34\lib\site-packages\django\forms\forms.py", line 161, in is_valid
    return self.is_bound and not self.errors
  File "C:\Python34\lib\site-packages\django\forms\forms.py", line 153, in errors
    self.full_clean()
  File "C:\Python34\lib\site-packages\django\forms\forms.py", line 364, in full_clean
    self._post_clean()
  File "C:\Python34\lib\site-packages\django\forms\models.py", line 377, in _post_clean
    exclude = self._get_validation_exclusions()
  File "C:\Python34\lib\site-packages\django\forms\models.py", line 309, in _get_validation_exclusions
    for f in self.instance._meta.fields:
AttributeError: 'NoneType' object has no attribute '_meta'
2017-04-19 13:57:21 - ERROR - base:handle_uncaught_exception:284 - Internal Server Error: /admin/approve/referee/
Traceback (most recent call last):
  File "C:\Python34\lib\site-packages\django\core\handlers\base.py", line 149, in get_response
    response = self.process_exception_by_middleware(e, request)
  File "C:\Python34\lib\site-packages\django\core\handlers\base.py", line 147, in get_response
    response = wrapped_callback(request, *callback_args, **callback_kwargs)
  File "C:\Python34\lib\site-packages\django\contrib\auth\decorators.py", line 23, in _wrapped_view
    return view_func(request, *args, **kwargs)
  File "D:\Github Projects\PhDPortal\app\admin_views.py", line 109, in admin_approve_referee
    if user_form.is_valid() and referee_form.is_valid():
  File "C:\Python34\lib\site-packages\django\forms\forms.py", line 161, in is_valid
    return self.is_bound and not self.errors
  File "C:\Python34\lib\site-packages\django\forms\forms.py", line 153, in errors
    self.full_clean()
  File "C:\Python34\lib\site-packages\django\forms\forms.py", line 364, in full_clean
    self._post_clean()
  File "C:\Python34\lib\site-packages\django\forms\models.py", line 377, in _post_clean
    exclude = self._get_validation_exclusions()
  File "C:\Python34\lib\site-packages\django\forms\models.py", line 309, in _get_validation_exclusions
    for f in self.instance._meta.fields:
AttributeError: 'NoneType' object has no attribute '_meta'
2017-04-19 13:57:42 - ERROR - base:handle_uncaught_exception:284 - Internal Server Error: /admin/approve/referee/
Traceback (most recent call last):
  File "C:\Python34\lib\site-packages\django\core\handlers\base.py", line 149, in get_response
    response = self.process_exception_by_middleware(e, request)
  File "C:\Python34\lib\site-packages\django\core\handlers\base.py", line 147, in get_response
    response = wrapped_callback(request, *callback_args, **callback_kwargs)
  File "C:\Python34\lib\site-packages\django\contrib\auth\decorators.py", line 23, in _wrapped_view
    return view_func(request, *args, **kwargs)
  File "D:\Github Projects\PhDPortal\app\admin_views.py", line 109, in admin_approve_referee
    if user_form.is_valid() and referee_form.is_valid():
  File "C:\Python34\lib\site-packages\django\forms\forms.py", line 161, in is_valid
    return self.is_bound and not self.errors
  File "C:\Python34\lib\site-packages\django\forms\forms.py", line 153, in errors
    self.full_clean()
  File "C:\Python34\lib\site-packages\django\forms\forms.py", line 364, in full_clean
    self._post_clean()
  File "C:\Python34\lib\site-packages\django\forms\models.py", line 377, in _post_clean
    exclude = self._get_validation_exclusions()
  File "C:\Python34\lib\site-packages\django\forms\models.py", line 309, in _get_validation_exclusions
    for f in self.instance._meta.fields:
AttributeError: 'NoneType' object has no attribute '_meta'
2017-04-19 13:58:52 - ERROR - base:handle_uncaught_exception:284 - Internal Server Error: /admin/approve/referee/
Traceback (most recent call last):
  File "C:\Python34\lib\site-packages\django\core\handlers\base.py", line 149, in get_response
    response = self.process_exception_by_middleware(e, request)
  File "C:\Python34\lib\site-packages\django\core\handlers\base.py", line 147, in get_response
    response = wrapped_callback(request, *callback_args, **callback_kwargs)
  File "C:\Python34\lib\site-packages\django\contrib\auth\decorators.py", line 23, in _wrapped_view
    return view_func(request, *args, **kwargs)
  File "D:\Github Projects\PhDPortal\app\admin_views.py", line 107, in admin_approve_referee
    print(user_form.first_name)
  File "C:\Python34\lib\site-packages\django\db\models\fields\__init__.py", line 188, in __str__
    model = self.model
AttributeError: 'CharField' object has no attribute 'model'
2017-04-19 13:59:09 - ERROR - base:handle_uncaught_exception:284 - Internal Server Error: /admin/approve/referee/
Traceback (most recent call last):
  File "C:\Python34\lib\site-packages\django\core\handlers\base.py", line 149, in get_response
    response = self.process_exception_by_middleware(e, request)
  File "C:\Python34\lib\site-packages\django\core\handlers\base.py", line 147, in get_response
    response = wrapped_callback(request, *callback_args, **callback_kwargs)
  File "C:\Python34\lib\site-packages\django\contrib\auth\decorators.py", line 23, in _wrapped_view
    return view_func(request, *args, **kwargs)
  File "D:\Github Projects\PhDPortal\app\admin_views.py", line 107, in admin_approve_referee
    print(str(user_form.first_name))
  File "C:\Python34\lib\site-packages\django\db\models\fields\__init__.py", line 188, in __str__
    model = self.model
AttributeError: 'CharField' object has no attribute 'model'
2017-04-19 13:59:55 - ERROR - base:handle_uncaught_exception:284 - Internal Server Error: /admin/approve/referee/
Traceback (most recent call last):
  File "C:\Python34\lib\site-packages\django\core\handlers\base.py", line 149, in get_response
    response = self.process_exception_by_middleware(e, request)
  File "C:\Python34\lib\site-packages\django\core\handlers\base.py", line 147, in get_response
    response = wrapped_callback(request, *callback_args, **callback_kwargs)
  File "C:\Python34\lib\site-packages\django\contrib\auth\decorators.py", line 23, in _wrapped_view
    return view_func(request, *args, **kwargs)
  File "D:\Github Projects\PhDPortal\app\admin_views.py", line 108, in admin_approve_referee
    if user_form.is_valid() and referee_form.is_valid():
  File "C:\Python34\lib\site-packages\django\forms\forms.py", line 161, in is_valid
    return self.is_bound and not self.errors
  File "C:\Python34\lib\site-packages\django\forms\forms.py", line 153, in errors
    self.full_clean()
  File "C:\Python34\lib\site-packages\django\forms\forms.py", line 364, in full_clean
    self._post_clean()
  File "C:\Python34\lib\site-packages\django\forms\models.py", line 377, in _post_clean
    exclude = self._get_validation_exclusions()
  File "C:\Python34\lib\site-packages\django\forms\models.py", line 309, in _get_validation_exclusions
    for f in self.instance._meta.fields:
AttributeError: 'NoneType' object has no attribute '_meta'
2017-04-19 14:04:03 - ERROR - base:handle_uncaught_exception:284 - Internal Server Error: /admin/approve/referee/
Traceback (most recent call last):
  File "C:\Python34\lib\site-packages\django\core\handlers\base.py", line 149, in get_response
    response = self.process_exception_by_middleware(e, request)
  File "C:\Python34\lib\site-packages\django\core\handlers\base.py", line 147, in get_response
    response = wrapped_callback(request, *callback_args, **callback_kwargs)
  File "C:\Python34\lib\site-packages\django\contrib\auth\decorators.py", line 23, in _wrapped_view
    return view_func(request, *args, **kwargs)
  File "D:\Github Projects\PhDPortal\app\admin_views.py", line 108, in admin_approve_referee
    if user_form.is_valid() and referee_form.is_valid():
  File "C:\Python34\lib\site-packages\django\forms\forms.py", line 161, in is_valid
    return self.is_bound and not self.errors
  File "C:\Python34\lib\site-packages\django\forms\forms.py", line 153, in errors
    self.full_clean()
  File "C:\Python34\lib\site-packages\django\forms\forms.py", line 364, in full_clean
    self._post_clean()
  File "C:\Python34\lib\site-packages\django\forms\models.py", line 377, in _post_clean
    exclude = self._get_validation_exclusions()
  File "C:\Python34\lib\site-packages\django\forms\models.py", line 309, in _get_validation_exclusions
    for f in self.instance._meta.fields:
AttributeError: 'NoneType' object has no attribute '_meta'
2017-04-19 14:06:33 - ERROR - base:handle_uncaught_exception:284 - Internal Server Error: /admin/approve/referee/
Traceback (most recent call last):
  File "C:\Python34\lib\site-packages\django\core\handlers\base.py", line 149, in get_response
    response = self.process_exception_by_middleware(e, request)
  File "C:\Python34\lib\site-packages\django\core\handlers\base.py", line 147, in get_response
    response = wrapped_callback(request, *callback_args, **callback_kwargs)
  File "C:\Python34\lib\site-packages\django\contrib\auth\decorators.py", line 23, in _wrapped_view
    return view_func(request, *args, **kwargs)
  File "D:\Github Projects\PhDPortal\app\admin_views.py", line 108, in admin_approve_referee
    if user_form.is_valid() and referee_form.is_valid():
  File "C:\Python34\lib\site-packages\django\forms\forms.py", line 161, in is_valid
    return self.is_bound and not self.errors
  File "C:\Python34\lib\site-packages\django\forms\forms.py", line 153, in errors
    self.full_clean()
  File "C:\Python34\lib\site-packages\django\forms\forms.py", line 364, in full_clean
    self._post_clean()
  File "C:\Python34\lib\site-packages\django\forms\models.py", line 377, in _post_clean
    exclude = self._get_validation_exclusions()
  File "C:\Python34\lib\site-packages\django\forms\models.py", line 309, in _get_validation_exclusions
    for f in self.instance._meta.fields:
AttributeError: 'NoneType' object has no attribute '_meta'
2017-04-19 14:06:39 - ERROR - base:handle_uncaught_exception:284 - Internal Server Error: /admin/approve/referee/
Traceback (most recent call last):
  File "C:\Python34\lib\site-packages\django\core\handlers\base.py", line 149, in get_response
    response = self.process_exception_by_middleware(e, request)
  File "C:\Python34\lib\site-packages\django\core\handlers\base.py", line 147, in get_response
    response = wrapped_callback(request, *callback_args, **callback_kwargs)
  File "C:\Python34\lib\site-packages\django\contrib\auth\decorators.py", line 23, in _wrapped_view
    return view_func(request, *args, **kwargs)
  File "D:\Github Projects\PhDPortal\app\admin_views.py", line 108, in admin_approve_referee
    if user_form.is_valid() and referee_form.is_valid():
  File "C:\Python34\lib\site-packages\django\forms\forms.py", line 161, in is_valid
    return self.is_bound and not self.errors
  File "C:\Python34\lib\site-packages\django\forms\forms.py", line 153, in errors
    self.full_clean()
  File "C:\Python34\lib\site-packages\django\forms\forms.py", line 364, in full_clean
    self._post_clean()
  File "C:\Python34\lib\site-packages\django\forms\models.py", line 377, in _post_clean
    exclude = self._get_validation_exclusions()
  File "C:\Python34\lib\site-packages\django\forms\models.py", line 309, in _get_validation_exclusions
    for f in self.instance._meta.fields:
AttributeError: 'NoneType' object has no attribute '_meta'
2017-04-19 14:06:45 - ERROR - base:handle_uncaught_exception:284 - Internal Server Error: /admin/approve/referee/
Traceback (most recent call last):
  File "C:\Python34\lib\site-packages\django\core\handlers\base.py", line 149, in get_response
    response = self.process_exception_by_middleware(e, request)
  File "C:\Python34\lib\site-packages\django\core\handlers\base.py", line 147, in get_response
    response = wrapped_callback(request, *callback_args, **callback_kwargs)
  File "C:\Python34\lib\site-packages\django\contrib\auth\decorators.py", line 23, in _wrapped_view
    return view_func(request, *args, **kwargs)
  File "D:\Github Projects\PhDPortal\app\admin_views.py", line 108, in admin_approve_referee
    if user_form.is_valid() and referee_form.is_valid():
  File "C:\Python34\lib\site-packages\django\forms\forms.py", line 161, in is_valid
    return self.is_bound and not self.errors
  File "C:\Python34\lib\site-packages\django\forms\forms.py", line 153, in errors
    self.full_clean()
  File "C:\Python34\lib\site-packages\django\forms\forms.py", line 364, in full_clean
    self._post_clean()
  File "C:\Python34\lib\site-packages\django\forms\models.py", line 377, in _post_clean
    exclude = self._get_validation_exclusions()
  File "C:\Python34\lib\site-packages\django\forms\models.py", line 309, in _get_validation_exclusions
    for f in self.instance._meta.fields:
AttributeError: 'NoneType' object has no attribute '_meta'
2017-04-19 14:10:07 - ERROR - base:handle_uncaught_exception:284 - Internal Server Error: /admin/approve/referee/
Traceback (most recent call last):
  File "C:\Python34\lib\site-packages\django\core\handlers\base.py", line 149, in get_response
    response = self.process_exception_by_middleware(e, request)
  File "C:\Python34\lib\site-packages\django\core\handlers\base.py", line 147, in get_response
    response = wrapped_callback(request, *callback_args, **callback_kwargs)
  File "C:\Python34\lib\site-packages\django\contrib\auth\decorators.py", line 23, in _wrapped_view
    return view_func(request, *args, **kwargs)
  File "D:\Github Projects\PhDPortal\app\admin_views.py", line 108, in admin_approve_referee
    if user_form.is_valid() and referee_form.is_valid():
  File "C:\Python34\lib\site-packages\django\forms\forms.py", line 161, in is_valid
    return self.is_bound and not self.errors
  File "C:\Python34\lib\site-packages\django\forms\forms.py", line 153, in errors
    self.full_clean()
  File "C:\Python34\lib\site-packages\django\forms\forms.py", line 364, in full_clean
    self._post_clean()
  File "C:\Python34\lib\site-packages\django\forms\models.py", line 377, in _post_clean
    exclude = self._get_validation_exclusions()
  File "C:\Python34\lib\site-packages\django\forms\models.py", line 309, in _get_validation_exclusions
    for f in self.instance._meta.fields:
AttributeError: 'NoneType' object has no attribute '_meta'
2017-04-19 14:11:26 - ERROR - base:handle_uncaught_exception:284 - Internal Server Error: /admin/add/referee/
Traceback (most recent call last):
  File "C:\Python34\lib\site-packages\django\core\handlers\base.py", line 149, in get_response
    response = self.process_exception_by_middleware(e, request)
  File "C:\Python34\lib\site-packages\django\core\handlers\base.py", line 147, in get_response
    response = wrapped_callback(request, *callback_args, **callback_kwargs)
  File "C:\Python34\lib\site-packages\django\contrib\auth\decorators.py", line 23, in _wrapped_view
    return view_func(request, *args, **kwargs)
  File "D:\Github Projects\PhDPortal\app\admin_views.py", line 51, in admin_add_referee
    if user_form.is_valid() and referee_form.is_valid():
  File "C:\Python34\lib\site-packages\django\forms\forms.py", line 161, in is_valid
    return self.is_bound and not self.errors
  File "C:\Python34\lib\site-packages\django\forms\forms.py", line 153, in errors
    self.full_clean()
  File "C:\Python34\lib\site-packages\django\forms\forms.py", line 364, in full_clean
    self._post_clean()
  File "C:\Python34\lib\site-packages\django\forms\models.py", line 377, in _post_clean
    exclude = self._get_validation_exclusions()
  File "C:\Python34\lib\site-packages\django\forms\models.py", line 309, in _get_validation_exclusions
    for f in self.instance._meta.fields:
AttributeError: 'NoneType' object has no attribute '_meta'
2017-04-19 14:13:46 - ERROR - base:handle_uncaught_exception:284 - Internal Server Error: /admin/add/referee/
Traceback (most recent call last):
  File "C:\Python34\lib\site-packages\django\core\handlers\base.py", line 149, in get_response
    response = self.process_exception_by_middleware(e, request)
  File "C:\Python34\lib\site-packages\django\core\handlers\base.py", line 147, in get_response
    response = wrapped_callback(request, *callback_args, **callback_kwargs)
  File "C:\Python34\lib\site-packages\django\contrib\auth\decorators.py", line 23, in _wrapped_view
    return view_func(request, *args, **kwargs)
  File "D:\Github Projects\PhDPortal\app\admin_views.py", line 51, in admin_add_referee
    if user_form.is_valid() and referee_form.is_valid():
  File "C:\Python34\lib\site-packages\django\forms\forms.py", line 161, in is_valid
    return self.is_bound and not self.errors
  File "C:\Python34\lib\site-packages\django\forms\forms.py", line 153, in errors
    self.full_clean()
  File "C:\Python34\lib\site-packages\django\forms\forms.py", line 364, in full_clean
    self._post_clean()
  File "C:\Python34\lib\site-packages\django\forms\models.py", line 377, in _post_clean
    exclude = self._get_validation_exclusions()
  File "C:\Python34\lib\site-packages\django\forms\models.py", line 309, in _get_validation_exclusions
    for f in self.instance._meta.fields:
AttributeError: 'NoneType' object has no attribute '_meta'
2017-04-19 14:25:25 - ERROR - base:handle_uncaught_exception:284 - Internal Server Error: /admin/approve/referee/
Traceback (most recent call last):
  File "C:\Python34\lib\site-packages\django\core\handlers\base.py", line 149, in get_response
    response = self.process_exception_by_middleware(e, request)
  File "C:\Python34\lib\site-packages\django\core\handlers\base.py", line 147, in get_response
    response = wrapped_callback(request, *callback_args, **callback_kwargs)
  File "C:\Python34\lib\site-packages\django\contrib\auth\decorators.py", line 23, in _wrapped_view
    return view_func(request, *args, **kwargs)
  File "D:\Github Projects\PhDPortal\app\admin_views.py", line 109, in admin_approve_referee
    check_user = User.objects.get(username = request.POST.get('username'))
  File "C:\Python34\lib\site-packages\django\db\models\manager.py", line 122, in manager_method
    return getattr(self.get_queryset(), name)(*args, **kwargs)
  File "C:\Python34\lib\site-packages\django\db\models\query.py", line 387, in get
    self.model._meta.object_name
django.contrib.auth.models.DoesNotExist: User matching query does not exist.
2017-04-19 14:25:32 - ERROR - base:handle_uncaught_exception:284 - Internal Server Error: /admin/approve/referee/
Traceback (most recent call last):
  File "C:\Python34\lib\site-packages\django\core\handlers\base.py", line 149, in get_response
    response = self.process_exception_by_middleware(e, request)
  File "C:\Python34\lib\site-packages\django\core\handlers\base.py", line 147, in get_response
    response = wrapped_callback(request, *callback_args, **callback_kwargs)
  File "C:\Python34\lib\site-packages\django\contrib\auth\decorators.py", line 23, in _wrapped_view
    return view_func(request, *args, **kwargs)
  File "D:\Github Projects\PhDPortal\app\admin_views.py", line 109, in admin_approve_referee
    check_user = User.objects.get(username = request.POST.get('username'))
  File "C:\Python34\lib\site-packages\django\db\models\manager.py", line 122, in manager_method
    return getattr(self.get_queryset(), name)(*args, **kwargs)
  File "C:\Python34\lib\site-packages\django\db\models\query.py", line 387, in get
    self.model._meta.object_name
django.contrib.auth.models.DoesNotExist: User matching query does not exist.
2017-04-19 14:27:00 - ERROR - base:handle_uncaught_exception:284 - Internal Server Error: /admin/approve/referee/
Traceback (most recent call last):
  File "C:\Python34\lib\site-packages\django\core\handlers\base.py", line 149, in get_response
    response = self.process_exception_by_middleware(e, request)
  File "C:\Python34\lib\site-packages\django\core\handlers\base.py", line 147, in get_response
    response = wrapped_callback(request, *callback_args, **callback_kwargs)
  File "C:\Python34\lib\site-packages\django\contrib\auth\decorators.py", line 23, in _wrapped_view
    return view_func(request, *args, **kwargs)
  File "D:\Github Projects\PhDPortal\app\admin_views.py", line 109, in admin_approve_referee
    check_user = User.objects.get(username = str(request.POST.get('username')))
  File "C:\Python34\lib\site-packages\django\db\models\manager.py", line 122, in manager_method
    return getattr(self.get_queryset(), name)(*args, **kwargs)
  File "C:\Python34\lib\site-packages\django\db\models\query.py", line 387, in get
    self.model._meta.object_name
django.contrib.auth.models.DoesNotExist: User matching query does not exist.
2017-04-19 14:27:32 - ERROR - base:handle_uncaught_exception:284 - Internal Server Error: /admin/approve/referee/
Traceback (most recent call last):
  File "C:\Python34\lib\site-packages\django\core\handlers\base.py", line 149, in get_response
    response = self.process_exception_by_middleware(e, request)
  File "C:\Python34\lib\site-packages\django\core\handlers\base.py", line 147, in get_response
    response = wrapped_callback(request, *callback_args, **callback_kwargs)
  File "C:\Python34\lib\site-packages\django\contrib\auth\decorators.py", line 23, in _wrapped_view
    return view_func(request, *args, **kwargs)
  File "D:\Github Projects\PhDPortal\app\admin_views.py", line 109, in admin_approve_referee
    check_user = User.objects.get(username = str(request.POST.get('username')))
  File "C:\Python34\lib\site-packages\django\db\models\manager.py", line 122, in manager_method
    return getattr(self.get_queryset(), name)(*args, **kwargs)
  File "C:\Python34\lib\site-packages\django\db\models\query.py", line 387, in get
    self.model._meta.object_name
django.contrib.auth.models.DoesNotExist: User matching query does not exist.
2017-04-19 14:32:19 - ERROR - base:handle_uncaught_exception:284 - Internal Server Error: /admin/approve/referee/
Traceback (most recent call last):
  File "C:\Python34\lib\site-packages\django\core\handlers\base.py", line 149, in get_response
    response = self.process_exception_by_middleware(e, request)
  File "C:\Python34\lib\site-packages\django\core\handlers\base.py", line 147, in get_response
    response = wrapped_callback(request, *callback_args, **callback_kwargs)
  File "C:\Python34\lib\site-packages\django\contrib\auth\decorators.py", line 23, in _wrapped_view
    return view_func(request, *args, **kwargs)
  File "D:\Github Projects\PhDPortal\app\admin_views.py", line 107, in admin_approve_referee
    user_form = UserForm(request.POST, instanse = existing_user)
  File "D:\Github Projects\PhDPortal\app\forms.py", line 67, in __init__
    super(UserForm, self).__init__(*args, **kwargs)
TypeError: __init__() got an unexpected keyword argument 'instanse'
2017-04-19 14:32:36 - ERROR - base:handle_uncaught_exception:284 - Internal Server Error: /admin/approve/referee/
Traceback (most recent call last):
  File "C:\Python34\lib\site-packages\django\core\handlers\base.py", line 149, in get_response
    response = self.process_exception_by_middleware(e, request)
  File "C:\Python34\lib\site-packages\django\core\handlers\base.py", line 147, in get_response
    response = wrapped_callback(request, *callback_args, **callback_kwargs)
  File "C:\Python34\lib\site-packages\django\contrib\auth\decorators.py", line 23, in _wrapped_view
    return view_func(request, *args, **kwargs)
  File "D:\Github Projects\PhDPortal\app\admin_views.py", line 116, in admin_approve_referee
    message = "You are added to the PhDPortal of IIIT-Allahabad.Please kindly check the Portal and update your Password.<br>Username is "+ str(request.POST.get('username')) + "<br>Password is" + passwd + "<br>"
NameError: name 'passwd' is not defined
2017-04-19 14:33:00 - ERROR - base:handle_uncaught_exception:284 - Internal Server Error: /admin/approve/referee/
Traceback (most recent call last):
  File "C:\Python34\lib\site-packages\django\core\handlers\base.py", line 149, in get_response
    response = self.process_exception_by_middleware(e, request)
  File "C:\Python34\lib\site-packages\django\core\handlers\base.py", line 147, in get_response
    response = wrapped_callback(request, *callback_args, **callback_kwargs)
  File "C:\Python34\lib\site-packages\django\contrib\auth\decorators.py", line 23, in _wrapped_view
    return view_func(request, *args, **kwargs)
  File "D:\Github Projects\PhDPortal\app\admin_views.py", line 117, in admin_approve_referee
    send_notification(user, new_user, notify, '')
NameError: name 'new_user' is not defined
2017-04-19 14:33:20 - ERROR - base:handle_uncaught_exception:284 - Internal Server Error: /admin/approve/referee/
Traceback (most recent call last):
  File "C:\Python34\lib\site-packages\django\core\handlers\base.py", line 149, in get_response
    response = self.process_exception_by_middleware(e, request)
  File "C:\Python34\lib\site-packages\django\core\handlers\base.py", line 147, in get_response
    response = wrapped_callback(request, *callback_args, **callback_kwargs)
  File "C:\Python34\lib\site-packages\django\contrib\auth\decorators.py", line 23, in _wrapped_view
    return view_func(request, *args, **kwargs)
  File "D:\Github Projects\PhDPortal\app\admin_views.py", line 124, in admin_approve_referee
    receiver = new_user
NameError: name 'new_user' is not defined
2017-04-19 14:33:53 - ERROR - base:handle_uncaught_exception:284 - Internal Server Error: /admin/approve/referee/
Traceback (most recent call last):
  File "C:\Python34\lib\site-packages\django\core\handlers\base.py", line 149, in get_response
    response = self.process_exception_by_middleware(e, request)
  File "C:\Python34\lib\site-packages\django\core\handlers\base.py", line 147, in get_response
    response = wrapped_callback(request, *callback_args, **callback_kwargs)
  File "C:\Python34\lib\site-packages\django\contrib\auth\decorators.py", line 23, in _wrapped_view
    return view_func(request, *args, **kwargs)
  File "D:\Github Projects\PhDPortal\app\admin_views.py", line 104, in admin_approve_referee
    existing_user = User.objects.get(username = request.POST.get('username'))
  File "C:\Python34\lib\site-packages\django\db\models\manager.py", line 122, in manager_method
    return getattr(self.get_queryset(), name)(*args, **kwargs)
  File "C:\Python34\lib\site-packages\django\db\models\query.py", line 387, in get
    self.model._meta.object_name
django.contrib.auth.models.DoesNotExist: User matching query does not exist.
2017-04-19 15:17:50 - ERROR - base:handle_uncaught_exception:284 - Internal Server Error: /admin/approve/referee/
Traceback (most recent call last):
  File "C:\Python34\lib\site-packages\django\core\handlers\base.py", line 149, in get_response
    response = self.process_exception_by_middleware(e, request)
  File "C:\Python34\lib\site-packages\django\core\handlers\base.py", line 147, in get_response
    response = wrapped_callback(request, *callback_args, **callback_kwargs)
  File "C:\Python34\lib\site-packages\django\contrib\auth\decorators.py", line 23, in _wrapped_view
    return view_func(request, *args, **kwargs)
  File "D:\Github Projects\PhDPortal\app\admin_views.py", line 107, in admin_approve_referee
    user_form = UserForm(request.POST, instance = existing_user)
  File "D:\Github Projects\PhDPortal\app\forms.py", line 67, in __init__
    super(UserForm, self).__init__(*args, **kwargs)
  File "C:\Python34\lib\site-packages\django\forms\models.py", line 282, in __init__
    object_data = model_to_dict(instance, opts.fields, opts.exclude)
  File "C:\Python34\lib\site-packages\django\forms\models.py", line 84, in model_to_dict
    opts = instance._meta
AttributeError: 'QuerySet' object has no attribute '_meta'
2017-04-19 15:18:31 - ERROR - base:handle_uncaught_exception:284 - Internal Server Error: /admin/approve/referee/
Traceback (most recent call last):
  File "C:\Python34\lib\site-packages\django\core\handlers\base.py", line 149, in get_response
    response = self.process_exception_by_middleware(e, request)
  File "C:\Python34\lib\site-packages\django\core\handlers\base.py", line 147, in get_response
    response = wrapped_callback(request, *callback_args, **callback_kwargs)
  File "C:\Python34\lib\site-packages\django\contrib\auth\decorators.py", line 23, in _wrapped_view
    return view_func(request, *args, **kwargs)
  File "D:\Github Projects\PhDPortal\app\admin_views.py", line 107, in admin_approve_referee
    user_form = UserForm(request.POST, instance = existing_user)
  File "D:\Github Projects\PhDPortal\app\forms.py", line 67, in __init__
    super(UserForm, self).__init__(*args, **kwargs)
  File "C:\Python34\lib\site-packages\django\forms\models.py", line 282, in __init__
    object_data = model_to_dict(instance, opts.fields, opts.exclude)
  File "C:\Python34\lib\site-packages\django\forms\models.py", line 84, in model_to_dict
    opts = instance._meta
AttributeError: 'QuerySet' object has no attribute '_meta'
2017-04-19 15:20:44 - ERROR - base:handle_uncaught_exception:284 - Internal Server Error: /admin/approve/referee/
Traceback (most recent call last):
  File "C:\Python34\lib\site-packages\django\core\handlers\base.py", line 149, in get_response
    response = self.process_exception_by_middleware(e, request)
  File "C:\Python34\lib\site-packages\django\core\handlers\base.py", line 147, in get_response
    response = wrapped_callback(request, *callback_args, **callback_kwargs)
  File "C:\Python34\lib\site-packages\django\contrib\auth\decorators.py", line 23, in _wrapped_view
    return view_func(request, *args, **kwargs)
  File "D:\Github Projects\PhDPortal\app\admin_views.py", line 107, in admin_approve_referee
    user_form = UserForm(request.POST, instance = existing_user)
  File "D:\Github Projects\PhDPortal\app\forms.py", line 67, in __init__
    super(UserForm, self).__init__(*args, **kwargs)
  File "C:\Python34\lib\site-packages\django\forms\models.py", line 282, in __init__
    object_data = model_to_dict(instance, opts.fields, opts.exclude)
  File "C:\Python34\lib\site-packages\django\forms\models.py", line 84, in model_to_dict
    opts = instance._meta
AttributeError: 'QuerySet' object has no attribute '_meta'
2017-04-19 15:21:11 - ERROR - base:handle_uncaught_exception:284 - Internal Server Error: /admin/approve/referee/
Traceback (most recent call last):
  File "C:\Python34\lib\site-packages\django\core\handlers\base.py", line 149, in get_response
    response = self.process_exception_by_middleware(e, request)
  File "C:\Python34\lib\site-packages\django\core\handlers\base.py", line 147, in get_response
    response = wrapped_callback(request, *callback_args, **callback_kwargs)
  File "C:\Python34\lib\site-packages\django\contrib\auth\decorators.py", line 23, in _wrapped_view
    return view_func(request, *args, **kwargs)
  File "D:\Github Projects\PhDPortal\app\admin_views.py", line 107, in admin_approve_referee
    user_form = UserForm(request.POST, instance = existing_user)
  File "D:\Github Projects\PhDPortal\app\forms.py", line 67, in __init__
    super(UserForm, self).__init__(*args, **kwargs)
  File "C:\Python34\lib\site-packages\django\forms\models.py", line 282, in __init__
    object_data = model_to_dict(instance, opts.fields, opts.exclude)
  File "C:\Python34\lib\site-packages\django\forms\models.py", line 84, in model_to_dict
    opts = instance._meta
AttributeError: 'QuerySet' object has no attribute '_meta'
2017-04-19 15:59:59 - ERROR - base:handle_uncaught_exception:284 - Internal Server Error: /admin/approve/referee/
Traceback (most recent call last):
  File "C:\Python34\lib\site-packages\django\core\handlers\base.py", line 149, in get_response
    response = self.process_exception_by_middleware(e, request)
  File "C:\Python34\lib\site-packages\django\core\handlers\base.py", line 147, in get_response
    response = wrapped_callback(request, *callback_args, **callback_kwargs)
  File "C:\Python34\lib\site-packages\django\contrib\auth\decorators.py", line 23, in _wrapped_view
    return view_func(request, *args, **kwargs)
  File "D:\Github Projects\PhDPortal\app\admin_views.py", line 108, in admin_approve_referee
    guide = Faculty.objects.get(user = guide_user)
  File "C:\Python34\lib\site-packages\django\db\models\manager.py", line 122, in manager_method
    return getattr(self.get_queryset(), name)(*args, **kwargs)
  File "C:\Python34\lib\site-packages\django\db\models\query.py", line 387, in get
    self.model._meta.object_name
app.models.DoesNotExist: Faculty matching query does not exist.
2017-04-19 16:00:02 - ERROR - base:handle_uncaught_exception:284 - Internal Server Error: /admin/approve/referee/
Traceback (most recent call last):
  File "C:\Python34\lib\site-packages\django\core\handlers\base.py", line 149, in get_response
    response = self.process_exception_by_middleware(e, request)
  File "C:\Python34\lib\site-packages\django\core\handlers\base.py", line 147, in get_response
    response = wrapped_callback(request, *callback_args, **callback_kwargs)
  File "C:\Python34\lib\site-packages\django\contrib\auth\decorators.py", line 23, in _wrapped_view
    return view_func(request, *args, **kwargs)
  File "D:\Github Projects\PhDPortal\app\admin_views.py", line 108, in admin_approve_referee
    guide = Faculty.objects.get(user = guide_user)
  File "C:\Python34\lib\site-packages\django\db\models\manager.py", line 122, in manager_method
    return getattr(self.get_queryset(), name)(*args, **kwargs)
  File "C:\Python34\lib\site-packages\django\db\models\query.py", line 387, in get
    self.model._meta.object_name
app.models.DoesNotExist: Faculty matching query does not exist.
2017-04-19 16:00:38 - ERROR - base:handle_uncaught_exception:284 - Internal Server Error: /admin/approve/referee/
Traceback (most recent call last):
  File "C:\Python34\lib\site-packages\django\core\handlers\base.py", line 149, in get_response
    response = self.process_exception_by_middleware(e, request)
  File "C:\Python34\lib\site-packages\django\core\handlers\base.py", line 147, in get_response
    response = wrapped_callback(request, *callback_args, **callback_kwargs)
  File "C:\Python34\lib\site-packages\django\contrib\auth\decorators.py", line 23, in _wrapped_view
    return view_func(request, *args, **kwargs)
  File "D:\Github Projects\PhDPortal\app\admin_views.py", line 108, in admin_approve_referee
    guide = Faculty.objects.get(user = guide_user)
  File "C:\Python34\lib\site-packages\django\db\models\manager.py", line 122, in manager_method
    return getattr(self.get_queryset(), name)(*args, **kwargs)
  File "C:\Python34\lib\site-packages\django\db\models\query.py", line 387, in get
    self.model._meta.object_name
app.models.DoesNotExist: Faculty matching query does not exist.
2017-04-19 16:00:40 - ERROR - base:handle_uncaught_exception:284 - Internal Server Error: /admin/approve/referee/
Traceback (most recent call last):
  File "C:\Python34\lib\site-packages\django\core\handlers\base.py", line 149, in get_response
    response = self.process_exception_by_middleware(e, request)
  File "C:\Python34\lib\site-packages\django\core\handlers\base.py", line 147, in get_response
    response = wrapped_callback(request, *callback_args, **callback_kwargs)
  File "C:\Python34\lib\site-packages\django\contrib\auth\decorators.py", line 23, in _wrapped_view
    return view_func(request, *args, **kwargs)
  File "D:\Github Projects\PhDPortal\app\admin_views.py", line 108, in admin_approve_referee
    guide = Faculty.objects.get(user = guide_user)
  File "C:\Python34\lib\site-packages\django\db\models\manager.py", line 122, in manager_method
    return getattr(self.get_queryset(), name)(*args, **kwargs)
  File "C:\Python34\lib\site-packages\django\db\models\query.py", line 387, in get
    self.model._meta.object_name
app.models.DoesNotExist: Faculty matching query does not exist.
